Workbook

Sheet Leeme
A1: CubeSat UD34 – Práctica 4 – PCB P2 OBC-ADCS: hoja de soporte
A2: Consulta de fuentes y precios: Moneda de análisis: USD; tasa EUR→USD editable en la hoja Costos.
A3: Colores: azul = dato de entrada; negro = fórmula; amarillo = supuesto o valor estimado que debe revisarse.

Sheet Especificaciones
A1: Requisito P3 | B1: ET / interfaz | C1: Función en P2 | D1: Implementación
A2: RF-02/RF-03 | B2: ET-05, ET-06, ET-08 | C2: Captura programada y archivo no volátil | D2: DCMI + DMA a SDRAM; eMMC 4 GB (≥1 GB útil)
A3: RF-05/RF-06 | B3: IF04, IF05 | C3: Telemetría y telecomando | D3: I2C1 a EPS; USART1 a UHF
A4: RF-04 | B4: IF06 | C4: Descarga de imágenes | D4: SPI2 a transmisor S (≥8 MHz)
A5: RF-07 | B5: ET-17 | C5: Determinación de actitud | D5: IMU SPI1, magnetómetro I2C2, 16 canales ADC solares, ≥10 Hz
A6: RF-08 | B6: ET-16, ET-18, IF08, IF09 | C6: Actuación de actitud | D6: 3 puentes H (PWM) + medición de corriente; 3 UART a ruedas
A7: RF-12, RNF-13 | B7: ET-23 | C7: Tiempo a bordo | D7: RTC compensado; error ≤0,5 s en 48 h
A8: RF-13, RNF-14 | B8: ET-24 | C8: Supervisión | D8: Latido a EPS cada ≤10 s; NRST controlado por EPS; IWDG interno
A9: RNF-12 | B9: ET-09, ET-10, ET-11 | C9: Recursos de cómputo | D9: Cortex-M7 ≥400 MHz, SDRAM 32 MB, 2 MB flash doble banco, QSPI NOR
A10: RNF-15 | B10: IF14 | C10: Prueba independiente | D10: SWD local + umbilical (SWD/UART) por el bus
A11: RA-01 | B11: ET-27 | C11: Temperatura | D11: Componentes con rango ≥ −20…+50 °C (preferible −40…+85 °C)
A12: RA-03 | B12: ET-22, ET-24 | C12: SEL/SEU | D12: LCL en P1 por riel; ECC en flash/RAM; doble imagen de arranque
... A14: RN-10 | B14: — | C14: Buenas prácticas | D14: ECSS-Q-ST-70-12C para diseño de PCB

Sheet Cambios_P3
A1: ID | B1: Decisión P3 afectada | C1: Cambio | D1: Efecto en el sistema
A2: C-01 | B2: TBD-01 (conectores) | C2: Resuelto: apilado PC/104 con 2× Samtec ESQ-126-39-G-D; FFC Hirose FH12 de 40 pines a P4; JST GH de 8 pines a paneles y ruedas. | D2: El resto de tarjetas debe adoptar la asignación de pines de la Tabla de conectores.
A3: C-02 | B3: ET-23 RTC ≤2 ppm | C3: Se adopta RV-3032-C7: ±1,5 ppm (0…50 °C) y ±2,5 ppm (−40…85 °C). | D3: Deriva peor caso 0,43 s en 48 h: sigue cumpliendo RNF-13 (≤0,5 s).
A4: C-03 | B4: OBC 0,90 W máx (Tabla de potencia P3) | C4: Pico calculado de P2: 1,57 W (MCU 400 MHz con todos los periféricos 220 mA, SDRAM 105 mA, eMMC 121 mA, NOR 25 mA, sensores 4 mA; valores de hoja de datos). | D4: Solo en ráfagas de captura/compresión (≈2 min/sesión): +0,02 Wh/órbita de peor caso; el balance diario (+1,8 Wh) no cambia de signo.
A5: C-04 | B5: I2C-2 compartido con la cámara (IF07) | C5: La configuración de la cámara pasa a I2C3 dedicado. | D5: Una falla en el cable de la cámara no bloquea magnetómetro ni RTC.
A6: C-05 | B6: Magnetómetro (clase MEMS) | C6: LIS2MDL en lugar de LIS3MDL. | D6: LIS3MDL está NRND en ST y obsoleto en DigiKey.
A7: C-06 | B7: Reloj lento del MCU | C7: El RTC externo entrega 32,768 kHz compensado al LSE del MCU (modo bypass). | D7: Se elimina el cristal de 32 kHz y la base de tiempo del MCU hereda la compensación.
A8: C-07 | B8: Magnetómetro en SPI junto con la IMU (diagrama de P2, P3) | C8: El magnetómetro LIS2MDL pasa a I2C2, compartido con el RTC; la IMU conserva su SPI1 dedicado. | D8: El LIS2MDL se comunica por I2C a 400 kHz, suficiente para 10 Hz (ET-17); SPI1 queda solo para la IMU, que necesita mayor tasa. No cambia ningún requisito.
A9: C-08 | B9: eMMC ASFC4G31M-51BIN (selección inicial de la P4) | C9: Se usa ASFC4G31MA-51BIN, misma familia, capacidad, tensiones y encapsulado. | D9: El M-51BIN está obsoleto (LTB 2025-06-03) y sin stock. El MA sube el costo de la eMMC a 39–41 USD y su Tabla 4 da 121 mA en el modo usado (C-03). Octopart también lo marca obsoleto (LTB 2026-06-30): comprar el lote pronto o buscar reemplazo.
A10: C-09 | B10: Cristal HSE ABM8-25.000MHZ-D2Y-T (CL 18 pF) elegido en la P4 | C10: Se usa ECS-250-8-33-JGN-TR (25 MHz, CL 8 pF, ESR 40 Ω, C0 5 pF, −40…85 °C) con condensadores de 6,8 pF. | D10: Con el ABM8, gmcrit = 3,08 mA/V supera el Gm_crit_max de 1,5 mA/V del STM32H743 (DS12110 Tabla 34; AN2867 §3.4): el arranque no estaba garantizado. Con el ECS, gmcrit = 0,67 mA/V. Costo similar (0,29–0,45 USD).
A11: C-10 | B11: eMMC ASFC4G31MA-51BIN (C-08) | C11: Se usa ISSI IS21EF04GP-JCLI (eMMC 5.1, 4 GB pSLC, −40…85 °C, VCC/VCCQ 2,7–3,6 V, 153 FBGA 11,5×13 mm con el mapa de bolas JEDEC). C10 (VDDi) = 1 µF. | D11: Octopart marca el ASFC4G31MA obsoleto (LTB 2026-06-30, LTD 2026-12-30). El ISSI está activo (Arrow; Suntsu 1.333 u el 2026-10-24) y su hoja sí da el condensador de VDDi (≥0,1 µF, 1 µF recomendado; Tabla 8.3 CREG 1 µF mín.). Consumo 120 mA (SDR52). Precio sin publicar: se cotiza por RFQ.
A12: C-12 | B12: eMMC IS21EF04GP-JCLI (153 bolas) y J9 FTSH-105-01-F-DV | C12: IS21EF04GP-JQLI (misma memoria, 100-LFBGA 14×18) y FTSH-105-01-L-DV-K (polarizado, pin 7 = KEY) | D12: Son los modelos de la librería de Altium que usa el equipo. Misma hoja de datos y mismo circuito; la JQLI está activa (Suntsu 312 u). El J9 polarizado evita conectar el depurador al revés.
A13: C-11 | B13: Pasivos «por definir en Altium» y precio estimado | C13: Referencia exacta de cada resistencia, condensador, shunt y ferrita (hoja BOM), con dieléctrico X7R/C0G y tensión ≥2× la de trabajo | D13: Cantidades exactas desde el esquemático de referencia (58 × 100 nF, 16 × 1 kΩ…); costo con precios por escala de LCSC/Future; ciclo de vida verificado

Sheet Seleccion
A1: Función | B1: Especificación | C1: Elegido | D1: Alternativas | E1: Justificación | F1: Fuente (sección)
A2: MCU | B2: ET-10/11, ET-07, RNF-12 | C2: STM32H743IIT6 (LQFP176) | D2: STM32H743ZIT6 (LQFP144); STM32H753 (crypto) | E2: Único encapsulado no-BGA con FMC-SDRAM 16 bits + DCMI 12 bits + SDMMC + QUADSPI simultáneos y ≥20 canales ADC; 1,62–3,6 V, −40…85 °C; 2 MB flash doble banco para dos imágenes. LQFP144 deja pocos pines para ADC tras FMC y DCMI. | F2: DS12110 §1 (características), §3.15 FMC, §3.16 QUADSPI, §3.24 DCMI; ficha DigiKey 497-17722-ND
A3: SDRAM | B3: ET-09 | C3: ISSI IS42S16160L-6TLI (256 Mb ×16) | D3: IS42S16160J-6TLI (no stock); Alliance AS4C16M16SA | E3: 32 MB a 3,3 V, 166 MHz (margen sobre FMC ≤100 MHz), −40…85 °C, TSOP-II (sin BGA). La versión J está en ‘available but not stocked’. | F3: Ficha ISSI/Avnet 256Mb SDRAM (refresco 8K/64 ms); DigiKey 706-IS42S16160L-6TLI-ND
A4: Almacenamiento | B4: ET-08, RNF-04 | C4: ISSI IS21EF04GP-JQLI (eMMC 5.1, 4 GB pSLC) | D4: Kingston EMMC04G-WT32-01G10; SD-NAND LGA-8 | E4: eMMC 5.1 industrial −40…85 °C, NAND pSLC (más ciclos de escritura que MLC); VCC 2,7–3,6 V y VCCQ 2,7–3,6 V (3,3 V como el MCU); 153 FBGA 11,5×13×1,0 mm con el mapa JEDEC. Reemplaza al ASFC4G31MA-51BIN, obsoleto (C-10). Activo (Arrow, Suntsu: 1.333 u, 2026-10-24). | F4: ISSI IS21/22EF04GP/08GP datasheet Rev. A2 (30-05-2024): §1.2 Tabla 1.1 (p. 7), §2 mapa de bolas (p. 14), §3 pines (p. 16), Tabla 8.1 tensiones, Tabla 8.3 (p. 41), §9.2 paquete (p. 52); Arrow y Suntsu (2026-10-24/25)
A5: Memoria de arranque | B5: ET-11, RNF-14 | C5: Winbond W25Q128JVSIQ (QSPI NOR 128 Mb) | D5: Micron MT25QL128; MRAM SPI | E5: Imagen de respaldo y parámetros; 133 MHz QSPI, −40…85 °C, SOIC-8 208 mil fácil de inspeccionar; alto stock. | F5: Hoja de datos W25Q128JV; DigiKey W25Q128JVSIQ-ND
A6: IMU | B6: ET-17 | C6: ST ISM330DHCXTR | D6: ST LSM6DSO; Bosch BMI088 | E6: Grado industrial −40…105 °C con compensación de temperatura; SPI dedicado; ±125 °/s seleccionable para resolución fina. | F6: Página de producto ST ISM330DHCX; DigiKey 497-19784-1-ND
A7: Magnetómetro | B7: ET-17 | C7: ST LIS2MDLTR | D7: ST LIS3MDL (NRND); PNI RM3100 (módulo grande) | E7: Activo, 1,71–3,6 V, −40…85 °C, LGA-12 2×2 mm; ±50 G cubre el campo terrestre (~0,3 G) con margen ante campos internos. | F7: Página ST LIS2MDL; Newark 07AH6648
A8: RTC | B8: ET-23, RNF-13 | C8: Micro Crystal RV-3032-C7 (2,5 ppm) | D8: Maxim DS3231M; RV-3028-C7 (1 ppm a 25 °C, sin compensación) | E8: Compensado de fábrica: ±1,5 ppm (0…50 °C), ±2,5 ppm (−40…85 °C); 160 nA; CLKOUT 32,768 kHz para el LSE del MCU. | F8: Página Micro Crystal RV-3032-C7; DigiKey 2195-RV-3032-C7…
A9: Puente H MTQ | B9: IF08, ET-18 | C9: TI DRV8837DSGR ×3 | D9: TI DRV8833 (doble); DRV8212 | E9: VM 0–11 V (5 V nominal) y 1,8 A frente a ≤0,12 A por eje; lógica 1,8–7 V; nSLEEP permite apagar las bobinas en reposo. | F9: Hoja de datos TI DRV8837; Mouser 595-DRV8837DSGR
A10: Medición de corriente MTQ | B10: IF08 | C10: TI INA180A2IDBVR ×3 | D10: INA219 (I2C); shunt + ADC directo | E10: Ganancia fija 50 V/V ±1 %, modo común −0,2…26 V (lado alto en 5 V), salida analógica al ADC del MCU. | F10: Página TI INA180; DigiKey 296-47653-1-ND
A11: Conector de apilado | B11: TBD-01, IF03–IF06, IF14 | C11: Samtec ESQ-126-39-G-D ×2 | D11: Samtec ESQ-126-37; conector propietario de la estructura | E11: Estándar PC/104 usado por estructuras 1U; 5,7 A por contacto (dato distribuidor); −55…125 °C. | F11: Master Electronics / Electro Sonic ESQ-126-39-G-D
A12: Conector cámara | B12: IF07 | C12: Hirose FH12-40S-0.5SH(55) | D12: TE / Amphenol FFC 0,5 mm | E12: 40 posiciones permiten intercalar 15 tierras con 21 señales; 0,5 A/contacto; −40…85 °C. | F12: Farnell 1324556
A13: Conectores paneles y ruedas | B13: IF08–IF10 | C13: JST SM08B-GHS-TB ×5 | D13: Molex PicoBlade | E13: Cierre por rampa (vibración), 1 A, 50 V; −25…85 °C cubre el rango interno −20…+50 °C. | F13: RS 175-5600

Sheet Conectores
A1: J1 – Samtec ESQ-126-39-G-D (H1, señales; pines no listados: paso sin conexión)
A2: Pin | B2: Red | C2: Interfaz P3
A3: 1 | B3: I2C1_SCL | C3: IF04
A4: 2 | B4: GND
A5: 3 | B5: I2C1_SDA | C5: IF04
A6: 4 | B6: GND
A7: 5 | B7: OBC_HB | C7: IF04 (latido OBC→EPS)
A8: 6 | B8: OBC_RST_N | C8: IF04 (EPS→NRST, colector abierto)
A9: 7 | B9: UHF_TXD | C9: IF05 (OBC→UHF)
A10: 8 | B10: UHF_RXD | C10: IF05
A11: 9 | B11: UHF_EN | C11: IF05
A12: 10 | B12: UHF_RST_N | C12: IF05
A13: 11 | B13: GND
A14: 12 | B14: GND
A15: 13 | B15: S_SCK | C15: IF06
A16: 14 | B16: S_MOSI | C16: IF06
A17: 15 | B17: S_MISO | C17: IF06
A18: 16 | B18: S_CS_N | C18: IF06
A19: 17 | B19: S_EN | C19: IF06
A20: 18 | B20: S_STATUS | C20: IF06
A21: 19 | B21: GND
A22: 20 | B22: GND
A23: 21 | B23: UMB_SWDIO | C23: IF14
A24: 22 | B24: UMB_SWCLK | C24: IF14
A25: 23 | B25: UMB_NRST | C25: IF14
A26: 24 | B26: UMB_TXD | C26: IF14 (UART5)
A27: 25 | B27: UMB_RXD | C27: IF14
A28: 26 | B28: GND
A30: J2 – Samtec ESQ-126-39-G-D (H2, potencia; pines no listados: paso sin conexión)
A31: Pin | B31: Red | C31: Interfaz P3
A32: 1 | B32: 3V3_SW_OBC | C32: IF03
A33: 2 | B33: 3V3_SW_OBC | C33: IF03
A34: 3 | B34: 3V3_SW_OBC | C34: IF03
A35: 4 | B35: GND
A36: 5 | B36: GND
A37: 6 | B37: GND
A38: 7 | B38: 3V3_SW_CAM | C38: IF03 (paso a P4)
A39: 8 | B39: 3V3_SW_CAM | C39: IF03
A40: 9 | B40: GND
A41: 10 | B41: GND
...

Sheet Calculos
A1: Cálculo | B1: Parámetro | C1: Valor | D1: Unidad | E1: Fuente / fórmula
A2: Consumo 3V3 máx | B2: MCU 400 MHz, todos los periféricos | C2: 220 | D2: mA | E2: Emcraft STM32H7 SOM (según hoja de datos STM32H75xB)
A3: Consumo 3V3 máx | B3: SDRAM auto-refresco (Idd5, grado -6) | C3: 105 | D3: mA | E3: IS42S16160L Rev. A, DC Electrical Characteristics 1, p. 18: Idd5 = 105 mA (máx. de la tabla)
A4: Consumo 3V3 máx | B4: eMMC lectura SDR52 (ICC + ICCQ) | C4: 120 | D4: mA | E4: IS21/22EF04GP (misma tabla para JCLI y JQLI) Rev. A2 (30-05-2024), Tabla 1.1, §1.2, p. 7: SDR52 lectura 20 mA ICC + 100 mA ICCQ (escritura 4 GB: 40 + 70 = 110 mA); modo usado: SDR 4 bits ≤50 MHz
A5: Consumo 3V3 máx | B5: NOR QSPI programa/borrado (peor caso) | C5: 25 | D5: mA | E5: W25Q128JV Rev J, §9.4 DC Electrical Characteristics: ICC4–ICC7 = 25 mA máx
A6: Consumo 3V3 máx | B6: IMU + MAG + RTC + 3×INA180 + pull-ups | C6: 4 | D6: mA | E6: INA180 0,26 mA máx c/u (TI); resto <1 mA (estimado)
A7: Consumo 3V3 máx | B7: Total P2 | C7: =$C$2+$C$3+$C$4+$C$5+$C$6 -> 474 | D7: mA | E7: Suma
A8: Consumo 3V3 máx | B8: Potencia P2 máxima | C8: =$C$7*3.3/1000 -> 1.5642 | D8: W | E8: P = V·I
A9: Consumo nominal | B9: Potencia P2 nominal (P3) | C9: 0.35 | D9: W | E9: P3 Tabla de potencia (clase Tabla 8-4 SoA)
A10: Paso de corriente | B10: 3V3_SW_CAM a P4 | C10: =0.8/3.3*1000 -> 242.42424 | D10: mA | E10: P3: cámara 0,80 W máx
A11: Paso de corriente | B11: 5V_SW_ADCS (MTQ + ruedas) | C11: =(1.47+1.13)/5*1000 -> 520 | D11: mA | E11: P3: MTQ 1,47 W, ruedas 1,13 W
A12: Paso de corriente | B12: 3V3 total por el conector | C12: =$C$7+$C$10 -> 716.42424 | D12: mA
A13: Ancho de pista (IPC-2221) | B13: Elevación de temperatura admitida | C13: 10 | D13: °C | E13: Supuesto conservador (vacío: sin convección)
A14: Ancho de pista (IPC-2221) | B14: Espesor de cobre 1 oz | C14: 1.378 | D14: mil | E14: 1 oz = 35 µm
A15: Ancho de pista (IPC-2221) | B15: Ancho mínimo externo para 3V3 total | C15: =((($C$12/1000)/(0.048*$C$13^0.44))^(1/0.725))/$C$14*0.0254 -> 0.1896271 | D15: mm | E15: A=(I/(k·ΔT^0.44))^(1/0.725), k=0,048 externo
A16: Ancho de pista (IPC-2221) | B16: Ancho mínimo interno para 3V3 total | C16: =((($C$12/1000)/(0.024*$C$13^0.44))^(1/0.725))/$C$14*0.0254 -> 0.4933035 | D16: mm | E16: k=0,024 interno
A17: Ancho de pista (IPC-2221) | B17: Ancho mínimo externo para 5V_ADCS | C17: =((($C$11/1000)/(0.048*$C$13^0.44))^(1/0.725))/$C$14*0.0254 -> 0.12188381 | D17: mm
A18: Caída de tensión | B18: Longitud de un tramo de distribución | C18: 60 | D18: mm | E18: Supuesto (tarjeta de ~90 mm)
A19: Caída de tensión | B19: Ancho de trazo evaluado | C19: 0.5 | D19: mm | E19: PCB-01
A20: Caída de tensión | B20: Caída en 3V3 con ese trazo | C20: =0.0000000172*($C$18/1000)/(($C$19/1000)*0.000035)*($C$12/1000)*1000 -> 42.248561 | D20: mV | E20: ΔV = ρ·L/(w·t)·I; ρCu = 1,72e-8 Ω·m
A21: Caída de tensión | B21: ¿Cumple ≤30 mV con trazo? | C21: =IF($C$20<=30,"Sí","No → usar plano L3") -> No → usar plano L3 | E21: PCB-01
A22: HSE | B22: Capacidad de carga del cristal CL | C22: 8 | D22: pF | E22: ECS-250-8-33-JGN-TR (ECX-32): CL = 8 pF
A23: HSE | B23: Capacidad parásita estimada | C23: 5 | D23: pF | E23: AN2867: típico 2–5 pF (se toma el máximo)
A24: HSE | B24: Condensador de carga calculado | C24: =2*($C$22-$C$23) -> 6 | D24: pF | E24: AN2867: CL = C1·C2/(C1+C2) + Cs → C1=C2=2(CL−Cs)
A25: HSE | B25: Valor normalizado | C25: =IF($C$24<=5.6,5.6,6.8) -> 6.8 | D25: pF | E25: Serie E12: 6,8 pF (CL efectiva 8,4 pF con Cs = 5 pF)
A26: Pull-up I2C1 | B26: Capacidad del bus estimada | C26: 100 | D26: pF | E26: Estimado (conector/FFC + entradas)
A27: Pull-up I2C1 | B27: Tiempo de subida máx 100 kHz (EPS por el bus) | C27: 1000 | D27: ns | E27: UM10204
A28: Pull-up I2C1 | B28: Rp máxima | C28: =$C$27/(0.8473*$C$26)*1000 -> 11802.195 | D28: Ω | E28: Rp(max)=tr/(0,8473·Cb) (UM10204)
A29: Pull-up I2C1 | B29: Rp mínima | C29: =(3.3-0.4)/0.003 -> 966.66667 | D29: Ω | E29: Rp(min)=(VDD−VOL)/IOL, 3 mA (UM10204)
A30: Pull-up I2C1 | B30: Rp elegida | C30: 4700 | D30: Ω | E30: Entre mínimo y máximo
A31: Pull-up I2C1 | B31: ¿Dentro de rango? | C31: =IF(AND($C$30>=$C$29,$C$30<=$C$28),"Sí","No") -> Sí
A32: Pull-up I2C2 | B32: Capacidad del bus estimada | C32: 50 | D32: pF | E32: Estimado (conector/FFC + entradas)
A33: Pull-up I2C2 | B33: Tiempo de subida máx 400 kHz (local) | C33: 300 | D33: ns | E33: UM10204
A34: Pull-up I2C2 | B34: Rp máxima | C34: =$C$33/(0.8473*$C$32)*1000 -> 7081.3171 | D34: Ω | E34: Rp(max)=tr/(0,8473·Cb) (UM10204)
A35: Pull-up I2C2 | B35: Rp mínima | C35: =(3.3-0.4)/0.003 -> 966.66667 | D35: Ω | E35: Rp(min)=(VDD−VOL)/IOL, 3 mA (UM10204)
A36: Pull-up I2C2 | B36: Rp elegida | C36: 2200 | D36: Ω | E36: Entre mínimo y máximo
A37: Pull-up I2C2 | B37: ¿Dentro de rango? | C37: =IF(AND($C$36>=$C$35,$C$36<=$C$34),"Sí","No") -> Sí
A38: Pull-up I2C3 | B38: Capacidad del bus estimada | C38: 60 | D38: pF | E38: Estimado (conector/FFC + entradas)
A39: Pull-up I2C3 | B39: Tiempo de subida máx 100 kHz (FFC a P4) | C39: 1000 | D39: ns | E39: UM10204
A40: Pull-up I2C3 | B40: Rp máxima | C40: =$C$39/(0.8473*$C$38)*1000 -> 19670.325 | D40: Ω | E40: Rp(max)=tr/(0,8473·Cb) (UM10204)
...

Sheet Restricciones
A1: ID | B1: Trazabilidad | C1: Restricción y alcance | D1: Tipo de fuente | E1: Fuente y fundamento | F1: Aplicación (dónde queda registrada) | G1: Verificación / estado
A2: PCB-01 | B2: ET-21, IF03 | C2: 3V3_SW_OBC: hasta 0,48 A (P2) + 0,24 A de paso a P4 = 0,72 A. Distribución por plano en L3; tramos en trazo ≥0,5 mm (IPC-2221 pide 0,49 mm en capa interna y 0,19 mm en externa con ΔT = 10 °C); caída total ≤30 mV (1 %). | D2: Inferencia propia | E2: Cálculo IPC-2221 + resistencia del cobre (hoja Calculos, filas Ancho/caída). | F2: Directiva: clase PWR_3V3 + regla Width (mín 0,5 / pref 1,0 mm). | G2: Revisión de reglas en PCB (guía siguiente). Estado: directiva definida.
A3: PCB-02 | B3: IF03, IF08, IF09 | C3: 5V_SW_ADCS: 0,52 A pico (MTQ 0,29 A + ruedas 0,23 A). Trazo ≥0,5 mm o polígono; caída ≤50 mV. | D3: Inferencia propia | E3: Cálculo IPC-2221; Tablas 5-3/5-4 de P3 para las cargas. | F3: Directiva: clase PWR_5V + regla Width. | G3: Estado: directiva definida.
A4: PCB-03 | B4: RA-05, ET-28 | C4: GND: plano continuo en L2 sin cortes bajo SDRAM, DCMI, SDMMC, QSPI ni HSE. | D4: Recomendación adoptada | E4: AN4938 (diseño de hardware STM32H7); ECSS-E-ST-20-07C. | F4: Nota en esquemático (hoja TOP) + regla de plano en PCB. | G4: Pendiente: inspección visual del plano en PCB.
A5: PCB-04 | B5: ET-10 | C5: Desacoplamiento VDD: 100 nF por pin VDD a ≤2 mm del pin y 4,7 µF de bulto en el paquete; vía a GND junto al pad. | D5: Exigida por fuente (valores); distancia = recomendación | E5: AN4938 (tabla de alimentación STM32H7). | F5: Nota junto a cada grupo de condensadores (MCU_CORE). | G5: Pendiente: revisión de ubicación.
A6: PCB-05 | B6: ET-10 | C6: VCAP1 (pin 81) y VCAP2 (pin 125) unidos entre sí (red VCAP), cada uno con 2,2 µF cerámico ESR <100 mΩ junto a su pin (el LQFP176 no tiene VCAP3). | D6: Exigida por fuente | E6: AN4938 Rev 7, §2.2, p. 12: «Connect VCAP1 pin to VCAP2 pin»; DS12110 Rev 11. | F6: Nota en MCU_CORE + clase VCAP (Width ≥0,3 mm). | G6: Estado: definido.
A7: PCB-06 | B7: ET-17 | C7: VDDA: ferrita desde VDD + 1 µF + 100 nF; VREF+: 47 Ω desde VDDA + 1 µF + 100 nF, junto a los pines. | D7: Exigida por fuente | E7: AN4938. | F7: Nota en MCU_CORE. | G7: Estado: definido.
A8: PCB-07 | B8: ET-10 | C8: HSE 25 MHz (ECS-250-8-33-JGN-TR, CL 8 pF): Y1 y C de 6,8 pF a ≤5 mm de OSC_IN/OSC_OUT; anillo de GND; sin señales bajo el cristal en L1/L2. | D8: Recomendación adoptada | E8: AN2867 Rev 24 (§3.4 y recomendaciones de PCB); gmcrit 0,67 mA/V < 1,5 mA/V (DS12110 Tabla 34). | F8: Nota + Room/Keepout en PCB. | G8: Pendiente en PCB.
A9: PCB-08 | B9: ET-09 | C9: Bus SDRAM: impedancia objetivo 50 Ω ±10 % sobre GND (L1/L4 con referencia L2/L3). | D9: Inferencia propia | E9: Ancho preliminar 0,35 mm en L1 sobre prepreg 0,21 mm (εr 4,4), fórmula IPC-2141; confirmar con calculadora del fabricante. | F9: Directiva: clase SDRAM + regla Width (0,35 mm) / Impedance si la versión lo admite. | G9: Pendiente: apilamiento definitivo (guía siguiente).
A10: PCB-09 | B10: ET-09 | C10: Bus SDRAM: diferencia de longitud dentro de cada grupo (datos, dirección/control) respecto a SDCLK ≤10 mm. | D10: Inferencia propia | E10: 10 mm ≈ 66 ps = 0,7 % del periodo de 10 ns a 100 MHz (hoja Calculos). | F10: Directiva: regla Matched Lengths (tolerancia 10 mm) en clase SDRAM. | G10: Estado: directiva definida.
A11: PCB-10 | B11: ET-09 | C11: U2 a ≤30 mm de U1; sin vías innecesarias (≤2 por red). | D11: Inferencia propia | E11: Retardo total <0,3 ns frente a margen de temporización a 100 MHz. | F11: Nota + Room SDRAM en PCB. | G11: Pendiente en PCB.
A12: PCB-11 | B12: IF07, ET-07 | C12: DCMI: J3 junto al MCU; recorrido en P2 ≤50 mm; diferencia de longitud datos–PIXCLK ≤10 mm; resistencia serie 33 Ω en origen (P4). | D12: Inferencia propia | E12: Periodo 20,8 ns a 48 MHz; FFC ≤80 mm (IF07). | F12: Directiva: clase DCMI + Matched Lengths. | G12: Estado: directiva definida.
... A31: PCB-30 | B31: RNF-15 | C31: Puntos de prueba (pad ≥1,0 mm) en 3V3_SW_OBC, 5V_SW_ADCS, 3V3_SW_CAM, GND×2, NRST, OBC_HB, I2C1, UART5; J9 accesible desde el borde. | D31: Recomendación adoptada | E31: Prueba de la tarjeta aislada (RNF-15). | F31: Componentes TP en el esquemático. | G31: Estado: definido.

Sheet Fabricacion
A1: Parámetro | B1: Valor adoptado / capacidad | C1: Observación
A2: Proveedor | B2: JLCPCB – Rigid PCB capabilities | C2: https://jlcpcb.com/capabilities/Capabilities
A3: Fecha de consulta | B3: 2026-10-07
A4: Capas | B4: 4 (señal / GND / 3V3 / señal) | C4: Disponible 1–32
A5: Material | B5: FR-4 | C5: Laminados grado A (Nan Ya, KB, Shengyi)
A6: Espesor | B6: 1,6 mm ±10 % | C6: 0,4–2,0 mm estándar
A7: Cobre | B7: Externo 1 oz; interno 1 oz | C7: Interno 0,5 oz por defecto, 1 oz opcional
A8: Acabado | B8: ENIG | C8: Requerido para pads BGA 0,2–0,25 mm
A9: Impedancia | B9: Controlada ±10 % con pila estándar del fabricante | C9: Calculadora JLCPCB
A10: Pista/espacio mín. | B10: 0,09/0,09 mm (multicapa, 1 oz); 3 mil en fanout BGA | C10: Se adopta 0,10/0,10 general
A11: Vía mín. | B11: 0,15/0,25 mm (taladro/diámetro); preferido taladro ≥0,2 mm | C11: Se adopta 0,30/0,50 general y 0,20/0,40 en BGA
A12: Anillo PTH | B12: Rec. 0,20 mm, mín. 0,15 mm (multicapa 1 oz)
A13: Pad-pista / pad-pad SMD | B13: 0,10 mm / 0,15 mm
A14: Puente de máscara | B14: 0,10 mm (verde) | C14: LQFP 0,5 mm compatible
A15: Vía en pad | B15: Rellena con epoxi y tapada (0,15–0,55 mm) | C15: Servicio especial para eMMC
A16: Cobre a borde | B16: ≥0,2 mm ruteado | C16: Se adopta 0,5 mm
A17: Serigrafía | B17: Alto ≥1,0 mm, trazo ≥0,15 mm, ≥0,15 mm a pads
A18: Tolerancia de agujero | B18: +0,13/−0,08 mm (PTH)
A19: Servicios especiales | B19: ENIG + vía en pad rellena y tapada + vía 0,2 mm con diámetro <0,45 mm (costo extra)

Sheet Directivas_Altium
A1: Clase / directiva | B1: Redes | C1: Regla o mecanismo | D1: Restricciones
A2: PWR_3V3 | B2: 3V3_SW_OBC, 3V3_SW_CAM, VDDA | C2: Net Class + Width (mín 0,5 mm, pref 1,0) | D2: PCB-01
A3: PWR_5V | B3: 5V_SW_ADCS (incluye VM de los DRV8837) | C3: Net Class + Width (mín 0,5 mm) | D3: PCB-02
A4: SDRAM | B4: SDRAM_D[0..15], SDRAM_A[0..12], SDRAM_BA0/1, SDRAM_NBL0/1, SDRAM_SDCLK, SDRAM_SDNRAS, SDRAM_SDNCAS, SDRAM_SDNWE, SDRAM_SDNE0, SDRAM_SDCKE0 | C4: Net Class + Width 0,35 mm + Matched Lengths 10 mm | D4: PCB-08, PCB-09
A5: DCMI | B5: DCMI_D[0..11], DCMI_PIXCLK, DCMI_HSYNC, DCMI_VSYNC | C5: Net Class + Matched Lengths 10 mm | D5: PCB-11
A6: SDMMC | B6: EMMC_CK, EMMC_CMD, EMMC_D[0..3] | C6: Net Class + Matched Lengths 5 mm | D6: PCB-12
A7: QSPI | B7: QSPI_CLK, QSPI_NCS, QSPI_IO[0..3] | C7: Net Class | D7: PCB-13
A8: MTQ | B8: MTQ_COILA[1..3], MTQ_COILB[1..3] | C8: Net Class + Width 0,25 mm | D8: PCB-17
A9: SUN_AN | B9: SUNA[1..4], SUNB[1..4], SUNC[1..4], SUND[1..4] | C9: Net Class + Clearance 0,3 mm | D9: PCB-18
A10: VCAP | B10: VCAP | C10: Net Class + Width 0,3 mm | D10: PCB-05
A11: Notas | B11: — | C11: Notas de esquemático: PCB-03, 04, 06, 07, 10, 16, 19, 20, 23, 24 | D11: —
A12: Pendientes en PCB | B12: — | C12: PCB-14 (fanout BGA), 15, 25–29 (reglas del fabricante y pila) | D12: —

Sheet Ciclo_de_vida
A1: Verificación de ciclo de vida de la BOM (2026-10-25). Regla: solo componentes activos (no NRND, no obsoletos, no LTB).
A2: Ref. | B2: Referencia | C2: Estado | D2: Fuente y fecha | E2: Disponibilidad / nota
A3: U1 | B3: STM32H743IIT6 | C3: Activo | D3: st.com, página STM32H743II (2026-10-25): «Active, in volume production», longevidad 10 años desde 2026-01-01 (hasta 01/2036) | E3: DigiKey, Future, RS
A4: U2 | B4: IS42S16160L-6TLI | C4: Activo | D4: DigiKey 706-IS42S16160L-6TLI (2026-10-25): Product status Active | E4: 33 u en DigiKey; reservar con anticipación para el lote de 1000
A5: U3 | B5: IS21EF04GP-JQLI (reemplaza ASFC4G31MA-51BIN) | C5: Activo | D5: Suntsu (Active, 312 u, 2026-10-26); misma familia que IS21EF04GP-JCLI (Arrow: Active). El ASFC4G31MA-51BIN es Obsoleto en Octopart (LTB 2026-06-30) | E5: Plazo de fábrica 52 semanas; precio por RFQ (C-10)
A6: U4 | B6: W25Q128JVSIQ | C6: Activo | D6: DigiKey W25Q128JVSIQ-ND (2026-10-25): Active | E6: 27.875 u en DigiKey
A7: U5 | B7: ISM330DHCXTR | C7: Activo | D7: st.com (2026-10-25): Active; longevidad 10 años desde 2023-01-01 (hasta 01/2033) | E7: —
A8: U6 | B8: LIS2MDLTR | C8: Activo | D8: st.com (2026-10-25): Active, in volume production | E8: —
A9: U7 | B9: RV-3032-C7-32.768KHZ-2.5PPM-TA-QC | C9: Activo | D9: Dasenic (variante TA-QA, misma familia): Active, 11.467 u; JLCPCB C5127802 listado | E9: —
A10: U8–U10 | B10: DRV8837DSGR | C10: Activo | D10: Digipart (2026-10-25): Part Status Active (TI) | E10: Newark 1.381 u
A11: U11–U13 | B11: INA180A2IDBVR | C11: Activo | D11: ti.com, part details (2026-10-25): ACTIVE | E11: —
A12: Y1 | B12: ECS-250-8-33-JGN-TR | C12: Activo | D12: Future Electronics (2026-10-25): Active; Mouser stock 3.669 | E12: —
A13: J1, J2 | B13: ESQ-126-39-G-D | C13: Activo (pedido a fábrica) | D13: Farnell 3550766: «Available to order», plazo de fábrica 6 semanas; DigiKey 616 u, Arrow 250 u (Mymectronic) | E13: La ficha de Master Electronics muestra a la vez todos los mensajes de estado (plantilla), con stock y plazo de fábrica de 2 semanas: no indica fin de vida
... A32: MCU_CORE FB1 | B32: BLM15AG601SN1D (Murata) | C32: Activo / en stock | D32: LCSC C76884: En stock: LCSC 1.353.700 u | E32: —

Sheet BOM
A1: Designadores | B1: Cant/tarjeta | C1: Descripción | D1: Fabricante | E1: MPN | F1: Encapsulado | G1: Proveedor | H1: Estado de cotización
A2: U1 | B2: 1 | C2: MCU Cortex-M7 2 MB/1 MB | D2: STMicroelectronics | E2: STM32H743IIT6 | F2: LQFP-176 24×24 | G2: DigiKey 497-17722-ND | H2: Cotizado (10 u); 100/1000 sin escala publicada → se usa 10 u
A3: U2 | B3: 1 | C3: SDRAM 256 Mb ×16 166 MHz | D3: ISSI | E3: IS42S16160L-6TLI | F3: TSOP-II-54 | G3: DigiKey 706-IS42S16160L-6TLI-ND | H3: Cotizado
A4: U3 | B4: 1 | C4: eMMC 5.1 4 GB pSLC industrial | D4: ISSI | E4: IS21EF04GP-JQLI | F4: 100-LFBGA 14×18 | G4: Suntsu / Avnet (RFQ, 2026-10-26) | H4: Activo (Suntsu: 312 u, 2026-10-26); precio sin publicar (RFQ): se usa provisionalmente el precio verificado de la eMMC anterior de igual capacidad
A5: U4 | B5: 1 | C5: NOR QSPI 128 Mb | D5: Winbond | E5: W25Q128JVSIQ | F5: SOIC-8 208 mil | G5: DigiKey W25Q128JVSIQ-ND | H5: Cotizado
A6: U5 | B6: 1 | C6: IMU 6 ejes industrial | D6: STMicroelectronics | E6: ISM330DHCXTR | F6: LGA-14 2,5×3 | G6: DigiKey 497-19784-1-ND | H6: Cotizado (1000 u vía zenode/DigiKey)
A7: U6 | B7: 1 | C7: Magnetómetro 3 ejes | D7: STMicroelectronics | E7: LIS2MDLTR | F7: LGA-12 2×2 | G7: Newark 07AH6648 | H7: Cotizado
A8: U7 | B8: 1 | C8: RTC compensado I2C | D8: Micro Crystal | E8: RV-3032-C7-32.768KHZ-2.5PPM-TA-QC | F8: SON-8 3,2×1,5 | G8: DigiKey / JLCPCB C5127802 | H8: Cotizado (1000 u: JLCPCB)
A9: U8–U10 | B9: 3 | C9: Puente H 1,8 A | D9: Texas Instruments | E9: DRV8837DSGR | F9: WSON-8 2×2 | G9: Mouser 595-DRV8837DSGR | H9: Cotizado
A10: U11–U13 | B10: 3 | C10: Amplificador de corriente G=50 | D10: Texas Instruments | E10: INA180A2IDBVR | F10: SOT-23-5 | G10: DigiKey 296-47653-1-ND | H10: Cotizado (sin escala 1000 → se usa 100 u)
A11: Y1 | B11: 1 | C11: Cristal 25 MHz 8 pF ±20 ppm, −40…85 °C | D11: ECS Inc. | E11: ECS-250-8-33-JGN-TR | F11: SMD 3,2×2,5 (4 pads) | G11: Mouser (ECS-250-8-33-JGN-TR), 2026-10-25 | H11: Cotizado; stock 3.669
A12: J1, J2 | B12: 2 | C12: Conector apilado PC/104 2×26 | D12: Samtec | E12: ESQ-126-39-G-D | F12: THT 2,54 mm | G12: Master Electronics | H12: Cotizado (mínimo 5)
A13: J3 | B13: 1 | C13: Conector FFC 40 pos 0,5 mm | D13: Hirose | E13: FH12-40S-0.5SH(55) | F13: SMD R/A | G13: Farnell 1324556 | H13: Cotizado (EUR)
... A31: MCU_CORE FB1 | B31: 1 | C31: Ferrita 600 Ω @100 MHz, 300 mA, 0,52 Ω DC (VDDA) | D31: Murata | E31: BLM15AG601SN1D | F31: 0402 | G31: LCSC C76884 | H31: Cotizado (escalas publicadas)
A33: Configuración: variante única, todos los componentes montados; no hay componentes opcionales ni DNP. TP1–TP11 son pads de prueba sin componente. Designadores del esquemático de referencia (hoja:designador; ×3 = canal MTQ repetido, ×4 = canal PANEL repetido); al anotar en Altium se reemplazan por los definitivos.
A34: Total de componentes montados por tarjeta | B34: =SUM(B2:B31) -> 134

Sheet Costos
A1: Tasa EUR→USD | B1: 1.1559
A2: TRM COP por USD | B2: 3158.43
A3: Componente | B3: Cant/tarjeta | C3: Moneda | D3: Mínimo | E3: Múltiplo | F3: Q1 | G3: Q2 | H3: Q3 | I3: Q4 | J3: Q5 | K3: Q6 | L3: Q7 | M3: Q8 | N3: P1 | O3: P2 | P3: P3 | Q3: P4 | R3: P5 | S3: P6 | T3: P7 | U3: P8 | V3: Lote 10: compra | W3: Precio u (USD) | X3: Costo | Y3: Sobrante | Z3: Lote 100: compra | AA3: Precio u (USD) | AB3: Costo | AC3: Sobrante | AD3: Lote 1000: compra | AE3: Precio u (USD) | AF3: Costo | AG3: Sobrante
A4: STM32H743IIT6 | B4: =BOM!B2 -> 1 | C4: USD | D4: 1 | E4: 1 | F4: 10 | G4: 1000000000 | H4: 1000000000 | I4: 1000000000 | J4: 1000000000 | K4: 1000000000 | L4: 1000000000 | M4: 1000000000 | N4: 14.03 | O4: 14.03 | P4: 14.03 | Q4: 14.03 | R4: 14.03 | S4: 14.03 | T4: 14.03 | U4: 14.03 | V4: =MAX(CEILING(B4*10,E4),D4) -> 10 | W4: =IFERROR(LOOKUP(V4,F4:M4,N4:U4),N4)*IF(C4="EUR",$B$1,1) -> 14.03 | X4: =V4*W4 -> 140.3 | Y4: =V4-B4*10 -> 0 | Z4: =MAX(CEILING(B4*100,E4),D4) -> 100 | AA4: =IFERROR(LOOKUP(Z4,F4:M4,N4:U4),N4)*IF(C4="EUR",$B$1,1) -> 14.03 | AB4: =Z4*AA4 -> 1403 | AC4: =Z4-B4*100 -> 0 | AD4: =MAX(CEILING(B4*1000,E4),D4) -> 1000 | AE4: =IFERROR(LOOKUP(AD4,F4:M4,N4:U4),N4)*IF(C4="EUR",$B$1,1) -> 14.03 | AF4: =AD4*AE4 -> 14030 | AG4: =AD4-B4*1000 -> 0
A5: IS42S16160L-6TLI | B5: =BOM!B3 -> 1 | C5: USD | D5: 1 | E5: 1 | F5: 1 | G5: 10 | H5: 25 | I5: 50 | J5: 100 | K5: 250 | L5: 500 | M5: 1000 | N5: 4.94 | O5: 4.603 | P5: 4.4656 | Q5: 4.3616 | R5: 4.2577 | S5: 4.12112 | T5: 4.01894 | U5: 3.91808 | V5: =MAX(CEILING(B5*10,E5),D5) -> 10 | W5: =IFERROR(LOOKUP(V5,F5:M5,N5:U5),N5)*IF(C5="EUR",$B$1,1) -> 4.603 | X5: =V5*W5 -> 46.03 | Y5: =V5-B5*10 -> 0 | Z5: =MAX(CEILING(B5*100,E5),D5) -> 100 | AA5: =IFERROR(LOOKUP(Z5,F5:M5,N5:U5),N5)*IF(C5="EUR",$B$1,1) -> 4.2577 | AB5: =Z5*AA5 -> 425.77 | AC5: =Z5-B5*100 -> 0 | AD5: =MAX(CEILING(B5*1000,E5),D5) -> 1000 | AE5: =IFERROR(LOOKUP(AD5,F5:M5,N5:U5),N5)*IF(C5="EUR",$B$1,1) -> 3.91808 | AF5: =AD5*AE5 -> 3918.08 | AG5: =AD5-B5*1000 -> 0
A6: IS21EF04GP-JQLI (precio provisional) | B6: =BOM!B4 -> 1 | C6: USD | D6: 1 | E6: 1 | F6: 1 | G6: 10 | H6: 100 | I6: 1000 | J6: 1000000000 | K6: 1000000000 | L6: 1000000000 | M6: 1000000000 | N6: 40.95 | O6: 39.62 | P6: 39 | Q6: 39 | R6: 39 | S6: 39 | T6: 39 | U6: 39 | V6: =MAX(CEILING(B6*10,E6),D6) -> 10 | W6: =IFERROR(LOOKUP(V6,F6:M6,N6:U6),N6)*IF(C6="EUR",$B$1,1) -> 39.62 | X6: =V6*W6 -> 396.2 | Y6: =V6-B6*10 -> 0 | Z6: =MAX(CEILING(B6*100,E6),D6) -> 100 | AA6: =IFERROR(LOOKUP(Z6,F6:M6,N6:U6),N6)*IF(C6="EUR",$B$1,1) -> 39 | AB6: =Z6*AA6 -> 3900 | AC6: =Z6-B6*100 -> 0 | AD6: =MAX(CEILING(B6*1000,E6),D6) -> 1000 | AE6: =IFERROR(LOOKUP(AD6,F6:M6,N6:U6),N6)*IF(C6="EUR",$B$1,1) -> 39 | AF6: =AD6*AE6 -> 39000 | AG6: =AD6-B6*1000 -> 0
A7: W25Q128JVSIQ | B7: =BOM!B5 -> 1 | C7: USD | D7: 1 | E7: 1 | F7: 1 | G7: 10 | H7: 25 | I7: 90 | J7: 180 | K7: 270 | L7: 540 | M7: 1080 | N7: 1.88 | O7: 1.762 | P7: 1.7116 | Q7: 1.64067 | R7: 1.60217 | S7: 1.5797 | T7: 1.54144 | U7: 1.50348 | V7: =MAX(CEILING(B7*10,E7),D7) -> 10 | W7: =IFERROR(LOOKUP(V7,F7:M7,N7:U7),N7)*IF(C7="EUR",$B$1,1) -> 1.762 | X7: =V7*W7 -> 17.62 | Y7: =V7-B7*10 -> 0 | Z7: =MAX(CEILING(B7*100,E7),D7) -> 100 | AA7: =IFERROR(LOOKUP(Z7,F7:M7,N7:U7),N7)*IF(C7="EUR",$B$1,1) -> 1.64067 | AB7: =Z7*AA7 -> 164.067 | AC7: =Z7-B7*100 -> 0 | AD7: =MAX(CEILING(B7*1000,E7),D7) -> 1000 | AE7: =IFERROR(LOOKUP(AD7,F7:M7,N7:U7),N7)*IF(C7="EUR",$B$1,1) -> 1.54144 | AF7: =AD7*AE7 -> 1541.44 | AG7: =AD7-B7*1000 -> 0
A8: ISM330DHCXTR | B8: =BOM!B6 -> 1 | C8: USD | D8: 1 | E8: 1 | F8: 10 | G8: 100 | H8: 1000 | I8: 1000000000 | J8: 1000000000 | K8: 1000000000 | L8: 1000000000 | M8: 1000000000 | N8: 6.756 | O8: 5.9632 | P8: 4.99 | Q8: 4.99 | R8: 4.99 | S8: 4.99 | T8: 4.99 | U8: 4.99 | V8: =MAX(CEILING(B8*10,E8),D8) -> 10 | W8: =IFERROR(LOOKUP(V8,F8:M8,N8:U8),N8)*IF(C8="EUR",$B$1,1) -> 6.756 | X8: =V8*W8 -> 67.56 | Y8: =V8-B8*10 -> 0 | Z8: =MAX(CEILING(B8*100,E8),D8) -> 100 | AA8: =IFERROR(LOOKUP(Z8,F8:M8,N8:U8),N8)*IF(C8="EUR",$B$1,1) -> 5.9632 | AB8: =Z8*AA8 -> 596.32 | AC8: =Z8-B8*100 -> 0 | AD8: =MAX(CEILING(B8*1000,E8),D8) -> 1000 | AE8: =IFERROR(LOOKUP(AD8,F8:M8,N8:U8),N8)*IF(C8="EUR",$B$1,1) -> 4.99 | AF8: =AD8*AE8 -> 4990 | AG8: =AD8-B8*1000 -> 0
A9: LIS2MDLTR | B9: =BOM!B7 -> 1 | C9: USD | D9: 1 | E9: 1 | F9: 10 | G9: 100 | H9: 1000 | I9: 1000000000 | J9: 1000000000 | K9: 1000000000 | L9: 1000000000 | M9: 1000000000 | N9: 2.71 | O9: 2.35 | P9: 2.08 | Q9: 2.08 | R9: 2.08 | S9: 2.08 | T9: 2.08 | U9: 2.08 | V9: =MAX(CEILING(B9*10,E9),D9) -> 10 | W9: =IFERROR(LOOKUP(V9,F9:M9,N9:U9),N9)*IF(C9="EUR",$B$1,1) -> 2.71 | X9: =V9*W9 -> 27.1 | Y9: =V9-B9*10 -> 0 | Z9: =MAX(CEILING(B9*100,E9),D9) -> 100 | AA9: =IFERROR(LOOKUP(Z9,F9:M9,N9:U9),N9)*IF(C9="EUR",$B$1,1) -> 2.35 | AB9: =Z9*AA9 -> 235 | AC9: =Z9-B9*100 -> 0 | AD9: =MAX(CEILING(B9*1000,E9),D9) -> 1000 | AE9: =IFERROR(LOOKUP(AD9,F9:M9,N9:U9),N9)*IF(C9="EUR",$B$1,1) -> 2.08 | AF9: =AD9*AE9 -> 2080 | AG9: =AD9-B9*1000 -> 0
A10: RV-3032-C7-32.768KHZ-2.5PPM-TA-QC | B10: =BOM!B8 -> 1 | C10: USD | D10: 1 | E10: 1 | F10: 10 | G10: 100 | H10: 1000 | I10: 1000000000 | J10: 1000000000 | K10: 1000000000 | L10: 1000000000 | M10: 1000000000 | N10: 2.38 | O10: 1.9573 | P10: 2.023 | Q10: 2.023 | R10: 2.023 | S10: 2.023 | T10: 2.023 | U10: 2.023 | V10: =MAX(CEILING(B10*10,E10),D10) -> 10 | W10: =IFERROR(LOOKUP(V10,F10:M10,N10:U10),N10)*IF(C10="EUR",$B$1,1) -> 2.38 | X10: =V10*W10 -> 23.8 | Y10: =V10-B10*10 -> 0 | Z10: =MAX(CEILING(B10*100,E10),D10) -> 100 | AA10: =IFERROR(LOOKUP(Z10,F10:M10,N10:U10),N10)*IF(C10="EUR",$B$1,1) -> 1.9573 | AB10: =Z10*AA10 -> 195.73 | AC10: =Z10-B10*100 -> 0 | AD10: =MAX(CEILING(B10*1000,E10),D10) -> 1000 | AE10: =IFERROR(LOOKUP(AD10,F10:M10,N10:U10),N10)*IF(C10="EUR",$B$1,1) -> 2.023 | AF10: =AD10*AE10 -> 2023 | AG10: =AD10-B10*1000 -> 0
A11: DRV8837DSGR | B11: =BOM!B9 -> 3 | C11: USD | D11: 1 | E11: 1 | F11: 10 | G11: 100 | H11: 1000 | I11: 1000000000 | J11: 1000000000 | K11: 1000000000 | L11: 1000000000 | M11: 1000000000 | N11: 0.623 | O11: 0.493 | P11: 0.405 | Q11: 0.405 | R11: 0.405 | S11: 0.405 | T11: 0.405 | U11: 0.405 | V11: =MAX(CEILING(B11*10,E11),D11) -> 30 | W11: =IFERROR(LOOKUP(V11,F11:M11,N11:U11),N11)*IF(C11="EUR",$B$1,1) -> 0.623 | X11: =V11*W11 -> 18.69 | Y11: =V11-B11*10 -> 0 | Z11: =MAX(CEILING(B11*100,E11),D11) -> 300 | AA11: =IFERROR(LOOKUP(Z11,F11:M11,N11:U11),N11)*IF(C11="EUR",$B$1,1) -> 0.493 | AB11: =Z11*AA11 -> 147.9 | AC11: =Z11-B11*100 -> 0 | AD11: =MAX(CEILING(B11*1000,E11),D11) -> 3000 | AE11: =IFERROR(LOOKUP(AD11,F11:M11,N11:U11),N11)*IF(C11="EUR",$B$1,1) -> 0.405 | AF11: =AD11*AE11 -> 1215 | AG11: =AD11-B11*1000 -> 0
A12: INA180A2IDBVR | B12: =BOM!B10 -> 3 | C12: USD | D12: 1 | E12: 1 | F12: 10 | G12: 100 | H12: 1000000000 | I12: 1000000000 | J12: 1000000000 | K12: 1000000000 | L12: 1000000000 | M12: 1000000000 | N12: 0.31 | O12: 0.2397 | P12: 0.2397 | Q12: 0.2397 | R12: 0.2397 | S12: 0.2397 | T12: 0.2397 | U12: 0.2397 | V12: =MAX(CEILING(B12*10,E12),D12) -> 30 | W12: =IFERROR(LOOKUP(V12,F12:M12,N12:U12),N12)*IF(C12="EUR",$B$1,1) -> 0.31 | X12: =V12*W12 -> 9.3 | Y12: =V12-B12*10 -> 0 | Z12: =MAX(CEILING(B12*100,E12),D12) -> 300 | AA12: =IFERROR(LOOKUP(Z12,F12:M12,N12:U12),N12)*IF(C12="EUR",$B$1,1) -> 0.2397 | AB12: =Z12*AA12 -> 71.91 | AC12: =Z12-B12*100 -> 0 | AD12: =MAX(CEILING(B12*1000,E12),D12) -> 3000 | AE12: =IFERROR(LOOKUP(AD12,F12:M12,N12:U12),N12)*IF(C12="EUR",$B$1,1) -> 0.2397 | AF12: =AD12*AE12 -> 719.1 | AG12: =AD12-B12*1000 -> 0
A13: ECS-250-8-33-JGN-TR | B13: =BOM!B11 -> 1 | C13: USD | D13: 1 | E13: 1 | F13: 1 | G13: 10 | H13: 100 | I13: 500 | J13: 1000 | K13: 1000000000 | L13: 1000000000 | M13: 1000000000 | N13: 0.45 | O13: 0.353 | P13: 0.32 | Q13: 0.307 | R13: 0.285 | S13: 0.285 | T13: 0.285 | U13: 0.285 | V13: =MAX(CEILING(B13*10,E13),D13) -> 10 | W13: =IFERROR(LOOKUP(V13,F13:M13,N13:U13),N13)*IF(C13="EUR",$B$1,1) -> 0.353 | X13: =V13*W13 -> 3.53 | Y13: =V13-B13*10 -> 0 | Z13: =MAX(CEILING(B13*100,E13),D13) -> 100 | AA13: =IFERROR(LOOKUP(Z13,F13:M13,N13:U13),N13)*IF(C13="EUR",$B$1,1) -> 0.32 | AB13: =Z13*AA13 -> 32 | AC13: =Z13-B13*100 -> 0 | AD13: =MAX(CEILING(B13*1000,E13),D13) -> 1000 | AE13: =IFERROR(LOOKUP(AD13,F13:M13,N13:U13),N13)*IF(C13="EUR",$B$1,1) -> 0.285 | AF13: =AD13*AE13 -> 285 | AG13: =AD13-B13*1000 -> 0
A14: ESQ-126-39-G-D | B14: =BOM!B12 -> 2 | C14: USD | D14: 5 | E14: 1 | F14: 5 | G14: 25 | H14: 50 | I14: 100 | J14: 250 | K14: 500 | L14: 1000 | M14: 1000000000 | N14: 12.96 | O14: 11.4 | P14: 10.88 | Q14: 9.88 | R14: 8.98 | S14: 8.59 | T14: 8.56 | U14: 8.56 | V14: =MAX(CEILING(B14*10,E14),D14) -> 20 | W14: =IFERROR(LOOKUP(V14,F14:M14,N14:U14),N14)*IF(C14="EUR",$B$1,1) -> 12.96 | X14: =V14*W14 -> 259.2 | Y14: =V14-B14*10 -> 0 | Z14: =MAX(CEILING(B14*100,E14),D14) -> 200 | AA14: =IFERROR(LOOKUP(Z14,F14:M14,N14:U14),N14)*IF(C14="EUR",$B$1,1) -> 9.88 | AB14: =Z14*AA14 -> 1976 | AC14: =Z14-B14*100 -> 0 | AD14: =MAX(CEILING(B14*1000,E14),D14) -> 2000 | AE14: =IFERROR(LOOKUP(AD14,F14:M14,N14:U14),N14)*IF(C14="EUR",$B$1,1) -> 8.56 | AF14: =AD14*AE14 -> 17120 | AG14: =AD14-B14*1000 -> 0
A15: FH12-40S-0.5SH(55) | B15: =BOM!B13 -> 1 | C15: EUR | D15: 1 | E15: 1 | F15: 1 | G15: 10 | H15: 100 | I15: 250 | J15: 500 | K15: 1000 | L15: 1000000000 | M15: 1000000000 | N15: 2.79 | O15: 1.89 | P15: 1.79 | Q15: 1.68 | R15: 1.6 | S15: 1.51 | T15: 1.51 | U15: 1.51 | V15: =MAX(CEILING(B15*10,E15),D15) -> 10 | W15: =IFERROR(LOOKUP(V15,F15:M15,N15:U15),N15)*IF(C15="EUR",$B$1,1) -> 2.184651 | X15: =V15*W15 -> 21.84651 | Y15: =V15-B15*10 -> 0 | Z15: =MAX(CEILING(B15*100,E15),D15) -> 100 | AA15: =IFERROR(LOOKUP(Z15,F15:M15,N15:U15),N15)*IF(C15="EUR",$B$1,1) -> 2.069061 | AB15: =Z15*AA15 -> 206.9061 | AC15: =Z15-B15*100 -> 0 | AD15: =MAX(CEILING(B15*1000,E15),D15) -> 1000 | AE15: =IFERROR(LOOKUP(AD15,F15:M15,N15:U15),N15)*IF(C15="EUR",$B$1,1) -> 1.745409 | AF15: =AD15*AE15 -> 1745.409 | AG15: =AD15-B15*1000 -> 0
... A33: BLM15AG601SN1D | B33: =BOM!B31 -> 1 | C33: USD | D33: 100 | E33: 100 | F33: 100 | G33: 1000 | H33: 3000 | I33: 10000 | J33: 50000 | K33: 1000000000 | L33: 1000000000 | M33: 1000000000 | N33: 0.0091 | O33: 0.0074 | P33: 0.0066 | Q33: 0.0044 | R33: 0.0042 | S33: 0.0042 | T33: 0.0042 | U33: 0.0042 | V33: =MAX(CEILING(B33*10,E33),D33) -> 100 | W33: =IFERROR(LOOKUP(V33,F33:M33,N33:U33),N33)*IF(C33="EUR",$B$1,1) -> 0.0091 | X33: =V33*W33 -> 0.91 | Y33: =V33-B33*10 -> 90 | Z33: =MAX(CEILING(B33*100,E33),D33) -> 100 | AA33: =IFERROR(LOOKUP(Z33,F33:M33,N33:U33),N33)*IF(C33="EUR",$B$1,1) -> 0.0091 | AB33: =Z33*AA33 -> 0.91 | AC33: =Z33-B33*100 -> 0 | AD33: =MAX(CEILING(B33*1000,E33),D33) -> 1000 | AE33: =IFERROR(LOOKUP(AD33,F33:M33,N33:U33),N33)*IF(C33="EUR",$B$1,1) -> 0.0074 | AF33: =AD33*AE33 -> 7.4 | AG33: =AD33-B33*1000 -> 0
A35: Tamaño del lote | B35: Costo de componentes del lote (USD) | C35: Costo por tarjeta (USD) | D35: Observaciones | E35: Costo del lote (COP) | F35: Costo por tarjeta (COP)
A36: 10 tarjetas | B36: =SUM(X4:X33) -> 1102.896 | C36: =B36/10 -> 110.2896 | D36: Mínimos de compra (100 u en pasivos de LCSC, 5 u en ESQ-126, paquetes de 10 en JST) generan sobrantes (columna Sobrante). | E36: =B36*$B$2 -> 3483419.9 | F36: =C36*$B$2 -> 348341.99
A37: 100 tarjetas | B37: =SUM(AB4:AB33) -> 9899.8683 | C37: =B37/100 -> 98.998683 | D37: La mayoría de los circuitos integrados ya están en su escala de 100 u. | E37: =B37*$B$2 -> 31268041 | F37: =C37*$B$2 -> 312680.41
A38: 1000 tarjetas | B38: =SUM(AF4:AF33) -> 94076.881 | C38: =B38/1000 -> 94.076881 | D38: MCU, INA180, FTSH y eMMC sin escala de 1000 publicada: se mantiene el último precio (conservador). | E38: =B38*$B$2 -> 2.9713524e+08 | F38: =C38*$B$2 -> 297135.24
A40: Precios cotizados en su moneda original (USD o EUR, columna C); EUR→USD con B1 y USD→COP con B2. No incluye fabricación de la PCB, ensamble, transporte ni impuestos.
A41: Configuración de costo: variante única, todos los componentes montados (sin DNP). Los puntos de prueba TP son pads de cobre, sin componente ni costo.
A42: Pasivos «Estimado»: LCSC solo publica el precio de su escala más alta («desde»); en el 100 nF, cuyas escalas sí están publicadas, el precio de 100 u es 1,8 veces el «desde». El efecto sobre el costo por tarjeta es menor de 0,1 USD.

Sheet Fuentes
A1: Notas de fuentes verificadas (enlaces y datos usados)
A2: # Notas de fuentes verificadas (Práctica 4, P2 OBC-ADCS) — consulta 2026-10-07
A3: - STM32H743IIT6 (ST, DS12110): Cortex-M7, LQFP176 24x24, 1.62-3.6 V, -40..85 C, 2 MB flash, 1 MB RAM (192k TCM, 864k SRAM, 4k backup),
A4: FMC SDRAM hasta 133 MHz (sinc.), QUADSPI 133 MHz, DCMI 8-14 bit hasta 80 MHz, 3 ADC 16-bit, 140 I/O, 4 USART + 4 UART, 6 SPI, 4 I2C, 2 SDMMC.
A5: 400 MHz/856 DMIPS (rev Y); 480 MHz/1027 DMIPS (rev V). DigiKey 497-17722-ND: 10 u = $14.03 (MX); TME 1 u 14.97 EUR. Lead 15 sem.
A6: - SDRAM ISSI IS42S16160L-6TLI (sustituye J, J-6TL obsoleto): 256 Mb 16Mx16, 166 MHz, 5.4 ns, 3.0-3.6 V, -40..85, TSOP-II 54 (10.16 mm).
A7: DigiKey 706-IS42S16160L-6TLI-ND: 1 $4.94, 10 $4.603, 25 $4.4656, 50 $4.3616, 100 $4.2577, 250 $4.12112, 500 $4.01894, 1000 $3.91808. Stock 33.
A8: Refresh 8K / 64 ms (industrial).
A9: - eMMC Alliance Memory ASFC4G31M-51BIN: 4 GB eMMC 5.1, MLC, VCC 2.7-3.6, VCCQ 1.7-1.95 o 2.7-3.6, -40..85, FBGA-153 (11.5x13), bus 1/4/8 bit, 0-200 MHz.
A10: Future Electronics (4155744): 1 $4.57, 10 $4.48, 25 $4.41, 75 $4.33, 150+ $4.23; tray 160; stock 773. Alt: Kingston EMMC04G-WT32-01G10 $59.69 (1).
A11: - QSPI NOR Winbond W25Q128JVSIQ: 128 Mb, 133 MHz, 2.7-3.6 V, -40..85, SOIC-8 208 mil. DigiKey W25Q128JVSIQ-ND (USD): 1 $1.88, 10 $1.762, 25 1.7116,
A12: 90 1.64067, 180 1.60217, 270 1.5797, 540 1.54144, 1080 1.50348, 5040 1.42083; tube 90; stock 27,875.
... A57: - Ciclo de vida (2026-10-25): hoja Ciclo_de_vida, con la fuente de cada componente.
