Workbook

Sheet Leeme
A1: CubeSat UD34 – Práctica 3: hoja de cálculo de soporte
A2: Contiene las matrices, la comparación de alternativas y los presupuestos del informe.
A3: Convención de colores: texto azul = dato de entrada editable; negro = fórmula; verde = vínculo a otra hoja; relleno amarillo = supuesto clave.
A4: Hojas: Parametros (entradas y cálculos de órbita y carga útil) · Requisitos · Especificaciones · Trazabilidad · HW_SW · Recursos · Alternativas · Matriz (ponderada y sensibilidad) · Potencia · Masa_Volumen · Datos · Enlace · Interfaces · Riesgos.
A5: Referencias entre corchetes: [proyecto] descripción del proyecto UD34; [cds] CubeSat Design Specification Rev. 14.1; [soapwr], [soagnc], [soaav], [soacom] NASA State-of-the-Art, cap. 3, 5, 8 y 9; [ecss20], [ecssemc], [ecsspcb] normas ECSS; [nasa41], [nasa42] NASA SE Handbook.
A6: Los contactos con Medellín (pases/día y minutos/día) provienen de la propagación de 10 días en calculos.py; aquí se ingresan como dato.

Sheet Parametros
A1: Parámetro | B1: Valor | C1: Unidad | D1: Fuente / fórmula
A2: Parámetro gravitacional terrestre μ | B2: 398600.44 | C2: km³/s² | D2: Constante
A3: Radio terrestre ecuatorial | B3: 6378.137 | C3: km | D3: Constante
A4: Coeficiente J2 | B4: 0.00108263 | C4: - | D4: Constante
A5: Altitud orbital | B5: 550 | C5: km | D5: [proyecto]
A6: Semieje mayor | B6: =$B$3+$B$5 -> 6928.137 | C6: km | D6: Re + h
A7: Período orbital | B7: =2*PI()*SQRT($B$6^3/$B$2)/60 -> 95.64988 | C7: min | D7: 2π√(a³/μ)
A8: Velocidad de la traza | B8: =SQRT($B$2/$B$6)*$B$3/$B$6 -> 6.9829355 | C8: km/s | D8: √(μ/a)·Re/a
A9: Inclinación heliosíncrona | B9: =DEGREES(ACOS(-(2*PI()/(365.2422*86400))/(1.5*SQRT($B$2/$B$6^3)*$B$4*($B$3/$B$6)^2))) -> 97.592931 | C9: ° | D9: Precesión nodal J2 = 360°/año
A10: Fracción de eclipse (β = 0) | B10: =ACOS(SQRT($B$5^2+2*$B$3*$B$5)/$B$6)/PI() -> 0.37231082 | C10: - | D10: Peor caso (S-02)
A11: Duración del eclipse | B11: =$B$10*$B$7 -> 35.611486 | C11: min
A12: Órbitas por día | B12: =1440/$B$7 -> 15.054906 | C12: -
A13: Tamaño de píxel | B13: 2.2 | C13: µm | D13: Sensor CMOS 5 MP (ET-05)
A14: Distancia focal | B14: 25 | C14: mm | D14: Lente (ET-03)
A15: Columnas leídas (ventana) | B15: 1296 | C15: px | D15: ET-04
A16: Filas del sensor | B16: 1944 | C16: px | D16: ET-05
A17: Bits por píxel | B17: 12 | C17: bit | D17: ET-02
A18: Número de bandas | B18: 4 | C18: - | D18: RF-01
A19: GSD en nadir | B19: =$B$5*1000*$B$13/$B$14/1000 -> 48.4 | C19: m | D19: H·p/f (Ec. 1)
A20: Ancho de franja | B20: =$B$15*$B$19/1000 -> 62.7264 | C20: km | D20: Ncol·GSD
A21: Filas por banda | B21: =INT($B$16/$B$18) -> 486 | C21: px
A22: Longitud de franja por banda | B22: =$B$21*$B$19/1000 -> 23.5224 | C22: km
A23: Datos por toma (crudo) | B23: =$B$15*$B$16*$B$17/8/10^6 -> 3.779136 | C23: MB
A24: Intervalo entre tomas | B24: 3 | C24: s | D24: ET-06
A25: Duración de la escena objetivo | B25: 60 | C25: s | D25: ET-06
A26: Tomas por sesión | B26: =CEILING(($B$25+$B$18*$B$22/$B$8)/$B$24,1)+1 -> 26 | C26: - | D26: Escena + barrido de las 4 franjas
A27: Razón de compresión sin pérdidas | B27: 2 | C27: - | D27: S-05
A28: Volumen por sesión (comprimido) | B28: =$B$26*$B$23/$B$27 -> 49.128768 | C28: MB
A29: Traslape entre tomas | B29: =1-$B$8*$B$24/$B$22 -> 0.10941033 | C29: - | D29: Debe ser > 0
A30: Exposición máxima | B30: =($B$19/2)/($B$8*1000)*1000 -> 3.4655912 | C30: ms | D30: Ec. 2
A31: Reloj de píxel | B31: 48 | C31: MHz | D31: ET-07
A32: Tiempo de lectura | B32: =$B$15*$B$16/($B$31*10^6)*1000 -> 52.488 | C32: ms
A33: Estabilidad máxima | B33: =DEGREES(($B$19/2)/($B$5*1000*$B$32/1000)) -> 0.048030298 | C33: °/s | D33: Ec. 3
A34: Cizalla por rolling shutter | B34: =$B$8*1000*$B$32/1000/$B$19 -> 7.5727339 | C34: px | D34: Se corrige en tierra
A35: Ciclos por muestra de compresión | B35: 700 | C35: ciclos | D35: S-06 (Emporda: 550-710)
A36: Reloj de CPU | B36: 400 | C36: MHz | D36: ET-10
A37: Tiempo de compresión por toma | B37: =$B$15*$B$16*$B$35/($B$36*10^6) -> 4.408992 | C37: s
A38: Compresión de una sesión (diferida) | B38: =$B$37*$B$26/60 -> 1.9105632 | C38: min | D38: Debe terminar antes del siguiente contacto
A39: Desplazamiento por 2° de error | B39: =$B$5*TAN(RADIANS(2)) -> 19.206423 | C39: km | D39: RNF-07
A40: Pases por día sobre Medellín (el ≥ 10°) | B40: 2.2 | C40: pases/día | D40: calculos_ud34.py (10 días)
...

Sheet Supuestos
A1: ID | B1: Supuesto | C1: Justificación / consecuencia
A2: S-01 | B2: Órbita circular heliosíncrona de 550 km, i=97,6°, hora local del nodo descendente 10:30. | C2: i calculada con la condición de precesión nodal J_2 (archivos de soporte). Coincide con la de AlAinSat-1, en SSO a 550 km (i=97,565°) [alainsat]. La hora 10:30 es la de Sentinel-2, elegida como compromiso entre iluminación y nubosidad [s2orbit].
A3: S-02 | B3: Eclipse de peor caso: 35,6 min de 95,6 min (β=0). | C3: Dimensiona batería y promedio de generación de forma conservadora.
A4: S-03 | B4: Estación de referencia en Medellín (6,25°N, 75,56°W), elevación mínima 10°; UHF: Yagi 16,3 dBi, 120 W, receptor con NF 2 dB; banda S: parábola de 2 m con G/T=4,9 dB/K. | C4: La estación no se diseña; se toman los parámetros de un kit comercial de estación para pequeños satélites [isisgs,ntnugs]. La antena UHF se toma a T_0=290 K (conservador). Si solo hubiera parábola de 1,2 m, ver riesgo R-05.
A5: S-04 | B5: No se usa receptor GNSS; la posición se propaga a bordo con SGP4 a partir de TLE cargados desde tierra. | C5: El error de TLE+SGP4 crece del orden de 1--3 km/día [sgp4]; con TLE nuevos cada ≤48 h el error queda ≤7 km, menor que media franja (31 km). Se ahorra la potencia y el volumen de un receptor.
A6: S-05 | B6: Compresión sin pérdidas a bordo con razón 2:1. | C6: CCSDS-123 es el estándar de compresión sin pérdidas para imágenes multiespectrales [ccsds120]; su implementación en ECOSTRESS logra típicamente 2,3:1 [kiely]. Con una razón de solo 1,5:1 una sesión ocupa 65,5 MB, se descarga en 1,3 días (<2, RNF-05) y 7 días ocupan 0,46 GB (<1 GB, ET-08): la arquitectura no cambia.
A7: S-06 | B7: Costo de compresión en software de 700 ciclos de reloj por muestra. | C7: La implementación de referencia de CCSDS-123 (Emporda) procesa ≈4,9 Msamples/s en un i7-7500U con 15 bandas de predicción [fjeldtvedt], es decir, ≈550--710 ciclos/muestra; se toma el valor alto. La compresión se hace después de la sesión desde memoria (Tabla recursos), por lo que un costo mayor solo alarga ese tiempo.
A8: S-07 | B8: Operación nominal de 4 sesiones de captura por semana; picos de 1 sesión/día. | C8: Coherente con la capacidad de descarga (Sección presupuestos) y con la nubosidad de la zona.
A9: S-08 | B9: Consumos, masas y tamaños tomados de productos de la misma clase: Tablas 3-1, 3-4 y 3-8 [soapwr], 5-3 a 5-7 [soagnc], 8-4 [soaav], 9-2 y 9-3 [soacom] y hojas de datos de referencia (Tabla pot). | C9: Nivel suficiente para demostrar viabilidad; se añade 20 % de margen. La masa de la óptica es la única estimación propia.
A10: S-09 | B10: Temperatura interna de operación entre -20 °C y +50 °C. | C10: Es el rango de ciclado térmico del estándar QB50 usado para CubeSats [alainsat] y el rango de operación exigido a radios CubeSat de NASA [altunc]. No se hace análisis térmico (no exigido [proyecto]).
A11: S-10 | B11: Altura útil de apilado interno de 95 mm. | C11: Una estructura 1U comercial ofrece un volumen interior de 98,4 mm de altura [spacemanic]; se reservan 3,4 mm para holguras y fijaciones. Condiciona la partición física (R-01).
A12: S-11 | B12: Misión de 6 meses en LEO: componentes COTS de rango industrial con mitigación de efectos de evento único. | C12: Práctica usual en CubeSats; hay OBC Cortex-M7 comerciales probados hasta 40 krad, y las mitigaciones recomendadas son watchdog, ECC y reinicio de alimentación [soaav]. El proyecto no exige análisis de radiación [proyecto].
... A15: S-14 | B15: Consumo de las radios: transmisor UHF 5,5 W a 30 dBm; transmisor S 5 W a 30 dBm; receptor UHF 0,24 W. | C15: Transceptores UHF comerciales consumen 3--5,5 W para 27--33 dBm (se toma el máximo) [pulsarvutrx] y <0,24 W en recepción [pulsarutrx]; un transmisor S de 2,2--2,3 GHz con QPSK y 1 Mbps útiles con r=1/2 consume <5 W a 30 dBm [pulsarstx].

Sheet Requisitos
A1: ID | B1: Tipo | C1: Requisito | D1: Origen / justificación | E1: Pr. | F1: Criterio de aceptación (método)
A2: Funcionales
A3: RF-02 | B3: F | C3: El satélite deberá ejecutar sesiones de captura programadas desde tierra por tiempo y objetivo. | D3: ConOps; las zonas cafeteras solo son visibles en algunos pases. | E3: A | F3: Plan con 3 capturas ejecutado en banco con tiempo simulado, error de disparo ≤10 ms (D).
A4: RF-03 | B4: F | C4: El satélite deberá conservar imágenes y telemetría en memoria no volátil hasta confirmar su descarga. | D4: Contactos intermitentes (≈2,2 pases/día). | E4: A | F4: Sin pérdida de archivos tras 10 cortes de energía durante escritura (P).
A5: RF-04 | B5: F | C5: El satélite deberá transmitir los datos de imagen a la estación de Medellín. | D5: Misión. | E5: A | F5: Transferencia de extremo a extremo con atenuador que reproduce la pérdida de ET-12, tasa de error de trama <10^-3 (P).
A6: RF-05 | B6: F | C6: El satélite deberá transmitir telemetría de tensiones, corrientes, temperaturas, modo y estado de subsistemas. | D6: Descripción del proyecto. | E6: A | F6: Todas las variables de la lista de telemetría presentes en la baliza y en el volcado (D).
A7: RF-06 | B7: F | C7: El satélite deberá recibir, validar y ejecutar telecomandos y reportar su ejecución. | D7: Descripción del proyecto. | E7: A | F7: 100 % de comandos válidos ejecutados y reconocidos; comandos corruptos rechazados (P).
A8: RF-07 | B8: F | C8: El satélite deberá estimar su actitud. | D8: Apuntar cámara, antena y paneles. | E8: A | F8: Sensores entregan datos a la tasa de ET-17; estimación verificada por simulación (A, P).
A9: RF-08 | B9: F | C9: El satélite deberá modificar su actitud para amortiguar la rotación, apuntar la cámara, apuntar la antena a la estación y exponer los paneles al Sol. | D9: Descripción del proyecto. | E9: A | F9: Polaridad y par de actuadores medidos (P); desempeño por simulación (A).
A10: RF-09 | B10: F | C10: El satélite deberá generar energía solar y almacenarla para operar en eclipse. | D10: Descripción del proyecto. | E10: A | F10: Carga de batería con simulador solar en rango de ET-19/20 (P).
A11: RF-10 | B11: F | C11: El satélite deberá permitir encender y apagar por comando cada subsistema no crítico. | D11: Gestión de energía y recuperación de fallas. | E11: A | F11: Cada salida conmutada responde a comando (P).
A12: RF-11 | B12: F | C12: El satélite deberá proteger cada línea de alimentación contra sobrecorriente y restablecerla automáticamente. | D12: Latch-up por radiación [soaav]; ECSS-E-ST-20 §5.8.1d,e [ecss20]. | E12: A | F12: Corto inducido: disparo y reconexión en tiempos de ET-22 sin afectar otras líneas (P).
A13: RF-12 | B13: F | C13: El satélite deberá mantener la hora y estimar su posición orbital a bordo. | D13: Programar capturas y pases sin GNSS (S-04). | E13: M | F13: Error de hora dentro de RNF-13 (P); SGP4 comparado con referencia (A).
A14: RF-13 | B14: F | C14: El satélite deberá pasar autónomamente a modo seguro ante batería baja, bloqueo del OBC o 48 h sin comandos. | D14: Protección de la misión. | E14: A | F14: Inyección de las tres fallas produce transición a modo seguro (D).
A15: RF-14 | B15: F | C15: El satélite deberá pasar de configuración de lanzamiento a operativa de forma autónoma tras la separación. | D15: Antena UHF plegada durante el lanzamiento. | E15: A | F15: Secuencia completa en banco activando los interruptores de despliegue (D).
A16: No funcionales
A17: RNF-02 | B17: NF | C17: El ancho de franja por banda deberá ser ≥50 km. | D17: Absorber el error de apuntamiento (19 km a 2°) y cubrir la región en un pase. | E17: A | F17: Cálculo con número de columnas (A).
A18: RNF-03 | B18: NF | C18: La resolución radiométrica deberá ser ≥10 bits. | D18: Diferencias pequeñas de reflectancia entre estados de vegetación. | E18: M | F18: Hoja de datos del sensor (I).
A19: RNF-04 | B19: NF | C19: El almacenamiento deberá guardar ≥7 días de capturas nominales sin descarga. | D19: Pérdida de pases o indisponibilidad de la estación. | E19: A | F19: Capacidad útil ≥ ET-08 (A, I).
A20: RNF-05 | B20: NF | C20: El sistema deberá descargar el volumen de una sesión en ≤2 días de contactos. | D20: Equilibrio entre generación y descarga de datos (MOE-2). | E20: A | F20: Presupuesto de enlace y contactos (A).
A21: RNF-06 | B21: NF | C21: Todos los enlaces deberán tener margen ≥3 dB a 10° de elevación. | D21: Margen estándar de enlace usado por NASA para CubeSats [altunc]. | E21: A | F21: Presupuesto de enlace (A).
A22: RNF-07 | B22: NF | C22: El error de apuntamiento de la cámara deberá ser ≤2° (3σ) durante la captura. | D22: Desplazamiento ≤19 km, menor que media franja. | E22: A | F22: Simulación ADCS con sensores de ET-17 (A).
A23: RNF-08 | B23: NF | C23: La estabilidad angular durante la captura deberá ser ≤0,04 °/s. | D23: Cizalla por lectura rolling < GSD/2 (Ec. est). | E23: A | F23: Simulación ADCS (A).
A24: RNF-09 | B24: NF | C24: El balance de energía diario deberá ser positivo con margen de 20 % sobre el consumo en el perfil de peor caso. | D24: Viabilidad energética. | E24: A | F24: Presupuesto de potencia (A).
A25: RNF-10 | B25: NF | C25: La profundidad de descarga de la batería deberá ser ≤20 % en la órbita de peor caso. | D25: ≈2750 ciclos en 6 meses. | E25: M | F25: Presupuesto (A); ciclo de carga en banco (P).
A26: RNF-11 | B26: NF | C26: El satélite deberá cumplir sus funciones durante al menos 6 meses. | D26: Supuesto obligatorio de la misión. | E26: A | F26: Degradación de paneles y ciclos de batería incluidos en los presupuestos (A).
A27: RNF-12 | B27: NF | C27: El procesamiento deberá ejecutar el control de actitud a ≥10 Hz con carga de CPU ≤70 % durante la captura y comprimir una sesión antes del siguiente contacto. | D27: Margen para el software futuro [soaav]. | E27: A | F27: Estimación (A) y medición en tarjeta de evaluación (P).
A28: RNF-13 | B28: NF | C28: El error de la hora a bordo deberá ser ≤0,5 s entre sincronizaciones. | D28: 1 s de error equivale a 7 km a lo largo de la traza. | E28: M | F28: Deriva medida en 48 h (P).
... A30: RNF-15 | B30: NF | C30: Cada PCB deberá poder alimentarse, programarse y probarse de forma independiente. | D30: Integración y prueba (Práctica 6). | E30: M | F30: Prueba de cada tarjeta aislada con fuente de banco (D).
A31: Ambientales
A32: RA-02 | B32: Am | C32: El hardware deberá disipar su calor sin convección. | D32: Vacío. | E32: A | F32: Elementos >0,5 W con camino térmico a estructura (A, I).
A33: RA-03 | B33: Am | C33: El hardware deberá tolerar SEL y SEU sin pérdida permanente de funciones durante la misión. | D33: Radiación en LEO; SEL destructivo en COTS [soaav]. | E33: A | F33: Mitigaciones de ET-22 y ET-24 implementadas (I); prueba de corto inducido (P).
A34: RA-04 | B34: Am | C34: El hardware deberá soportar la vibración y el choque del lanzamiento. | D34: CDS §3.1, §3.3 [cds]. | E34: A | F34: Niveles del proveedor o GEVS; en el curso: sujeción de componentes pesados (I).
A35: RA-05 | B35: Am | C35: Las emisiones internas no deberán degradar la sensibilidad del receptor UHF más de 1 dB. | D35: Pequeño frente al margen UHF (12,4 dB). ECSS-E-ST-20-07 [ecssemc]. | E35: A | F35: Piso de ruido con todos los subsistemas encendidos (P).
A36: Normativos
A37: RN-02 | B37: N | C37: Masa ≤2,00 kg y centro de masa a ±2 cm del centro geométrico. | D37: CDS §2.2.10, §2.2.11. | E37: A | F37: Pesaje y cálculo de CG (I, A).
A38: RN-03 | B38: N | C38: Energía cortada desde la entrega hasta el despliegue por interruptor(es) de despliegue y pin RBF; reinicio a estado de prelanzamiento si el interruptor conmuta. | D38: CDS §2.3.1, §2.3.2, §2.3.5. | E38: A | F38: Prueba de continuidad y de secuencia (P).
A39: RN-04 | B39: N | C39: Tres inhibidores independientes de RF y ninguna emisión antes de 45 min. | D39: CDS §2.3.7, §2.4.5. | E39: A | F39: Inspección del esquema y prueba de temporización (I, P).
A40: RN-05 | B40: N | C40: Tres inhibidores para elementos desplegables y espera ≥30 min. | D40: CDS §2.3.8, §2.4.4. | E40: A | F40: Inspección y prueba (I, P).
A41: RN-06 | B41: N | C41: Protección de carga y descarga de la batería contra celdas desbalanceadas. | D41: CDS §2.3.6. | E41: A | F41: Prueba de protección (P).
...

Sheet Especificaciones
A1: ID | B1: Requisitos | C1: Parámetro | D1: Valor / rango (unidad) | E1: Fundamento | F1: Verificación
A2: ET-01 | B2: RF-01 | C2: Bandas (centro/ancho) | D2: 560/35, 665/30, 705/15, 842/115 nm | E2: Bandas visibles e infrarrojas para vegetación [proyecto]. Centros y anchos iguales a las bandas B3, B4, B5 y B8 de Sentinel-2 [s2bands,s2hub], lo que permite comparar los índices con ese sensor: verde, rojo (absorción de la clorofila), borde rojo y NIR. | F2: I (filtro)
A3: ET-02 | B3: RNF-03 | C3: Cuantización | D3: 12 bits | E3: Supera el mínimo de 10 bits; ADC de 12 bits del sensor de referencia [mt9p031]. | F3: I
A4: ET-03 | B4: RNF-01 | C4: GSD nadir | D4: 48,4 m (±1 m por tolerancia de focal ±2 %) | E4: Ec. gsd. | F4: A
A5: ET-04 | B5: RNF-02 | C5: Franja | D5: 62,7 km (1296 columnas) | E5: 1296×GSD; margen de 25 %. | F5: A
A6: ET-05 | B6: RF-01, RF-02 | C6: Toma | D6: 1296×1944 px, 4 franjas de 486 filas, 3,78 MB | E6: Sensor de 2592×1944 px de 2,2 µm con lectura por ventana [mt9p031]; 12 bits empaquetados. | F6: A
A7: ET-06 | B7: RF-02, RNF-01 | C7: Exposición / intervalo / sesión | D7: ≤3,5 ms / 3 s / 26 tomas (≈75 s) | E7: Ec. exp; avance 20,9 km < franja de banda 23,5 km (11 % traslape). | F7: A, D
A8: ET-07 | B8: RF-01 | C8: Interfaz de la cámara | D8: Paralela 12 bits, PIXCLK ≤48 MHz, HSYNC/VSYNC; configuración I2C | E8: 48 Mp/s con E/S de 1,8 V [mt9p031]; 96 MB/s por DMA a SDRAM; lectura 52 ms. | F8: P
A9: ET-08 | B9: RF-03, RNF-04 | C9: Almacenamiento masivo | D9: ≥1 GB útil, no volátil con ECC | E9: 7 días × 49 MB + telemetría = 347 MB, margen ×3 (bloques dañados, copias). | F9: A
A10: ET-09 | B10: RNF-12 | C10: RAM de trabajo externa | D10: ≥16 MB (se elige 32 MB, 16 bits) | E10: 3 tomas de 5,04 MB en palabras de 16 bits (doble búfer + compresión). | F10: A
A11: ET-10 | B11: RNF-12 | C11: Capacidad de CPU | D11: ≥400 MHz clase Cortex-M7 con FPU; carga en captura ≈10 %; compresión de una sesión ≤3 min | E11: S-06: 700×1296×1944 ciclos = 4,4 s/toma, 26 tomas en ≈2 min en segundo plano; ADCS y C&DH con 10 % reservado (≈85 de 856 DMIPS a 400 MHz [stm32]). | F11: A, P
A12: ET-11 | B12: RNF-12, RNF-14 | C12: Memoria de programa | D12: ≥1 MB con ECC + 2 imágenes de arranque | E12: Dos imágenes de arranque (RNF-14); MCU de referencia con 2 MB de flash y 1 MB de RAM [stm32]. | F12: I
... A29: ET-28 | B29: RA-05 | C29: EMC de convertidores | D29: Frecuencia de conmutación fija y sincronizable ≥500 kHz; COM con blindaje y plano de tierra continuo | E29: Evita espurias variables en la banda de 437 MHz; ECSS-E-ST-20-07 [ecssemc]. | F29: P

Sheet Trazabilidad
A1: Req. | B1: ET | C1: Bloque | D1: Req. | E1: ET | F1: Bloque
A2: RF-01 | B2: 01, 05, 07 | C2: P4, P2 | D2: RNF-06 | E2: 12, 13 | F2: P3, antenas
A3: RF-02 | B3: 05, 06 | C3: P2, P4 | D3: RNF-07 | E3: 15, 17 | F3: P2, ruedas
A4: RF-03 | B4: 08 | C4: P2 | D4: RNF-08 | E4: 16 | F4: P2, ruedas
A5: RF-04 | B5: 12 | C5: P3, parche S | D5: RNF-09 | E5: 19, 21 | F5: P1, paneles
A6: RF-05 | B6: 13 | C6: P3, P2 | D6: RNF-10 | E6: 20 | F6: P1
A7: RF-06 | B7: 13 | C7: P3, P2 | D7: RNF-11 | E7: 19, 20, 22 | F7: Sistema
A8: RF-07 | B8: 17 | C8: P2, paneles | D8: RNF-12 | E8: 09, 10, 11 | F8: P2
A9: RF-08 | B9: 15, 16, 18 | C9: P2, ruedas, MTQ | D9: RNF-13 | E9: 23 | F9: P2
A10: RF-09 | B10: 19, 20 | C10: P1, paneles | D10: RNF-14 | E10: 24 | F10: P1, P2
A11: RF-10 | B11: 21 | C11: P1 | D11: RNF-15 | E11: Tabla if (IF14) | F11: Todas
A12: RF-11 | B12: 22 | C12: P1 | D12: RA-01 | E12: 27 | F12: Todas
... A19: RNF-04, 05 | B19: 08, 14 | C19: P2, P3 | D19: RN-07, 08, 09 | E19: -- (documental) | F19: Proyecto

Sheet HW_SW
A1: Función | B1: Tipo | C1: Recursos de hardware | D1: Responsabilidad del software futuro | E1: Justificación
A2: Generación y carga | B2: HW | C2: MPPT por cara, cargador 2S con balanceo, protección OV/UV/OC | D2: Solo leer telemetría y ajustar consignas | E2: Debe operar sin OBC (modo seguro, arranque).
A3: Distribución y protección | B3: Mixta | C3: LCL con reconexión automática, sensores de corriente, interruptores de carga | D3: Encender/apagar cargas, registrar eventos de disparo | E3: La protección es HW (tiempo de µs--ms); la política es SW.
A4: Supervisión y modos (FDIR) | B4: Mixta | C4: Watchdog interno + watchdog en EPS, contador de reinicios | D4: Máquina de estados de modos, detección de fallas, paso a modo seguro | E4: Evita que un SEU deje el satélite bloqueado.
A5: TT&C | B5: Mixta | C5: Transceptor UHF, antena, UART | D5: Tramas AX.25/CCSDS, validación, cola de comandos, balizas | E5: Radio integrada; protocolo cambiante en SW.
A6: Captura de imagen | B6: Mixta | C6: Sensor, lente, filtro, interfaz paralela + DMA, SDRAM, temporizador de disparo | D6: Configurar exposición y ganancia, planificar, marcar tiempo | E6: El flujo de 96 MB/s solo es posible por DMA; el disparo usa temporizador HW.
A7: Compresión y archivo | B7: SW | C7: CPU con FPU, SDRAM, eMMC | D7: Compresión sin pérdidas, catálogo, sistema de archivos con registro, miniaturas | E7: ≈2 min por sesión en segundo plano; evita un procesador dedicado.
A8: Descarga de imágenes | B8: Mixta | C8: Transmisor S, parche, SPI | D8: Segmentar, entramar (CCSDS TM), retransmisión selectiva, programar pases | E8: Tasa fija en HW; gestión de archivos en SW.
A9: Determinación de actitud | B9: Mixta | C9: IMU, magnetómetro, sensores solares, ADC | D9: Filtro de estimación, modelos de campo (IGRF) y Sol | E9: Algoritmos no se implementan; HW entrega datos a ≥10 Hz.
A10: Control de actitud | B10: Mixta | C10: Puentes H + bobinas, 3 ruedas con controlador propio | D10: B-dot, apuntamiento, seguimiento de estación, desaturación | E10: Lazo a 10 Hz en OBC; control de velocidad de ruedas local.
A11: Tiempo y órbita | B11: Mixta | C11: RTC con TCXO y respaldo | D11: SGP4, sincronización con tierra | E11: Sin GNSS (S-04).
A12: Térmico de batería | B12: HW + SW | C12: Calentador y termostato HW, NTC | D12: Ajustar consigna y leer temperatura | E12: Carga segura aun sin OBC.
A13: Secuencia post-despliegue | B13: Mixta | C13: Interruptores de despliegue, RBF, FET del quemador | D13: Temporizadores 30/45 min, verificación de despliegue | E13: Los inhibidores son físicos (CDS).

Sheet Recursos
A1: Recurso | B1: Necesidad derivada de las funciones | C1: Especificación resultante
A2: Procesamiento | B2: Compresión diferida de 4,4 s/toma, ≈2 min/sesión (S-06); ADCS a 10 Hz, SGP4 a 1 Hz, C&DH y protocolos dentro del 10 % reservado. | C2: Cortex-M7 ≥400 MHz con FPU (ET-10); carga en captura ≈10 %.
A3: RAM | B3: Búfer de tomas (5,04 MB c/u), pila RTOS, filtros ADCS (<256 kB). | C3: 1 MB interna con ECC + 32 MB SDRAM (ET-09).
A4: Memoria de programa | B4: RTOS + aplicación + 2 imágenes de arranque. | C4: ≥1 MB interna con ECC + NOR/MRAM externa (ET-11).
A5: Almacenamiento | B5: 7 días de capturas y telemetría = 347 MB. | C5: eMMC ≥1 GB útil (ET-08).
A6: Interfaces | B6: Cámara paralela; SDRAM; eMMC; 2 buses I2C (EPS / sensores separados); UART UHF; SPI banda S y SPI IMU; UART ruedas; 6 PWM; ≥6 ADC; ≈20 GPIO. | C6: MCU con interfaz de cámara paralela, controlador de memoria externa (SDRAM a 100 MHz), SDMMC y Quad-SPI [stm32]; hay OBC Cortex-M7 de 0,28--0,65 W (Tabla 8-4) [soaav].
A7: Temporización | B7: ADCS 10 Hz; telemetría 1 Hz (registro cada 60 s); baliza cada 30 s; disparo cada 3 s ±1 ms; PIXCLK 48 MHz; SDRAM 100 MHz. | C7: Temporizadores HW para disparo y PWM; RTC para tiempo absoluto.

Sheet Alternativas
A1: Decisión | B1: Opción A | C1: Opción B | D1: Resultado y razón
A2: D1 Procesamiento | B2: Centralizado: un MCU Cortex-M7 hace C&DH, ADCS, cámara y compresión. | C2: Distribuido: OBC de bajo consumo + procesador de carga útil (SoC ARM+FPGA con Linux y DDR3) + MCU de ADCS. | D2: A. La compresión cabe en el MCU (≈2 min por sesión, en segundo plano); B añade varios vatios al procesar (hasta 6 W en unidades de la Tabla 8-4 [soaav]), una tarjeta y enrutamiento DDR3.
A3: D2 División en PCBs | B3: 4 tarjetas: EPS, OBC-ADCS, COM, cabezal de cámara. | C3: 3 tarjetas: EPS, aviónica integrada (OBC+ADCS+radios), cabezal de cámara. | D3: A. Aísla el PA de banda S (1 W) del magnetómetro y del receptor UHF, y permite probar radios por separado; cuesta ≈13 mm de altura (cabe, Tabla vol).
A4: D3 Comunicación interna | B4: I2C para control/telemetría + enlaces dedicados (paralelo, SPI, UART) para datos. | C4: Bus CAN común a todas las tarjetas. | D4: A. Menos componentes y consumo; el riesgo de bloqueo de I2C se mitiga con dos buses separados, recuperación de bus y reinicio por LCL.
A5: D4 Integración de la carga útil | B5: Cámara integrada: el sensor entrega píxeles directamente al OBC. | C5: Módulo de cámara comercial con procesador y memoria propios (USB/SpaceWire). | D5: A. Menos volumen y potencia; control directo de temporización. B facilita integración pero pocos módulos 1U multiespectrales y costosos.
A6: D5 Potencia | B6: MPPT por cara + bus de batería 2S no regulado + convertidores conmutados en punto de carga. | C6: Transferencia directa de energía (DET) + bus regulado único de 5 V. | D6: A. El punto de máxima potencia cambia con la temperatura de cada cara; el MPPT recupera esa pérdida y el bus no regulado alimenta radios con alta eficiencia.
A7: D6 Paneles | B7: Fijos en 4 caras laterales. | C7: Desplegables (2--4 alas). | D7: A. El balance es positivo con paneles fijos (Tabla pot); B requiere mecanismos y 3 inhibidores más.
A8: D7 Enlaces con tierra | B8: UHF (TT&C) + banda S (imágenes). | C8: Solo UHF. | D8: A. UHF descarga ≈444 kB/día frente a 49 MB por sesión: B incumple RF-04/RNF-05.
A9: D8 ADCS | B9: Magnetorquers + 3 ruedas; sensores solares, magnetómetro, giróscopo. | C9: Solo magnetorquers con los mismos sensores (o con rastreador estelar). | D9: A. Los magnetorquers solos no suelen lograr estabilización en tres ejes [soagnc], que la captura (RNF-07/08) y el apuntamiento de la antena S exigen; un rastreador estelar (0,65 W o más, Tabla 5-5) no es necesario para 2°.

Sheet Matriz
A1: Criterio | B1: Peso | C1: A | D1: B | E1: Peso (sensib.) | F1: Justificación
A2: Consumo de energía | B2: 25 | C2: 4 | D2: 3 | E2: 10 | F2: A: MCU ≈0,35 W. B: procesador de carga útil de hasta 6 W al procesar, aunque se apague el resto del tiempo (Tabla 8-4) [soaav].
A3: Volumen y masa | B3: 20 | C3: 4 | D3: 2 | E3: 20 | F3: B agrega una tarjeta (≈12 mm): excede la altura disponible (S-10).
A4: Capacidad de procesamiento | B4: 15 | C4: 3 | D4: 5 | E4: 30 | F4: A cumple (captura con ≈10 % de CPU y compresión de una sesión en ≈2 min); B permite procesamiento avanzado (p. ej., detección de nubes) no exigido.
A5: Complejidad y riesgo técnico | B5: 15 | C5: 4 | D5: 2 | E5: 15 | F5: B: DDR3, secuencia de encendido del SoC, Linux y tres firmwares.
A6: Integración y prueba | B6: 10 | C6: 4 | D6: 3 | E6: 10 | F6: A: un solo firmware; B: más interfaces, pero módulos probables por separado.
A7: Integridad de señal y EMC | B7: 10 | C7: 3 | D7: 2 | E7: 10 | F7: A: SDRAM a 100 MHz y bus paralelo a 48 MHz (cortos). B: DDR3 con impedancia controlada y más capas.
A8: Costo y disponibilidad | B8: 5 | C8: 4 | D8: 3 | E8: 5 | F8: MCU y SDRAM de amplia disponibilidad; SoC y DDR3 con más costo.
A9: Suma de pesos | B9: =SUM(B2:B8) -> 100 | E9: =SUM(E2:E8) -> 100
A10: Total A (sobre 100) | C10: =SUMPRODUCT($B$2:$B$8,C2:C8)/5 -> 75
A11: Total B (sobre 100) | D11: =SUMPRODUCT($B$2:$B$8,D2:D8)/5 -> 57
A12: Sensibilidad: total A | C12: =SUMPRODUCT($E$2:$E$8,C2:C8)/5 -> 72
A13: Sensibilidad: total B | D13: =SUMPRODUCT($E$2:$E$8,D2:D8)/5 -> 63
A14: Escala 1 (malo) a 5 (excelente). Total = Σ(peso × nota)/5. Sensibilidad: peso de procesamiento 30 y de energía 10.

Sheet Potencia
A1: Entradas de generación y batería
A2: Parámetro | B2: Valor | C2: Unidad | D2: Fuente
A3: Área de celda | B3: 30.18 | C3: cm² | D3: Celda TJ en cara 1U
A4: Eficiencia de celda | B4: 0.295 | C4: - | D4: 3G30-Adv, Tabla 3-1 [soapwr]
A5: Constante solar | B5: 1361 | C5: W/m²
A6: Celdas por cara | B6: 2 | C6: - | D6: ET-19
A7: Factor de temperatura | B7: 0.85 | C7: - | D7: k_deg
A8: Degradación 6 meses | B8: 0.95 | C8: - | D8: k_deg
A9: Eficiencia MPPT y conversión | B9: 0.9 | C9: - | D9: k_deg
A10: Pérdidas de cableado | B10: 0.97 | C10: - | D10: k_deg
A11: Factor geométrico (2 caras a 45°) | B11: 1.41 | C11: - | D11: Actitud nominal
A12: Capacidad de celda | B12: 3.35 | C12: Ah | D12: NCR18650B, Tabla 3-4 [soapwr]
A13: Tensión nominal de celda | B13: 3.6 | C13: V
A14: Celdas en serie | B14: 2 | C14: - | D14: 2S1P
A15: Margen sobre consumo | B15: 0.2 | C15: - | D15: RNF-09
A16: Órbitas de peor caso por día | B16: 3 | C16: - | D16: Perfil de diseño
A17: Potencia por cara BOL | B17: =$B$6*$B$3/10^4*$B$5*$B$4 -> 2.4234238 | C17: W
A18: Generación promedio orbital EOL | B18: =$B$11*B17*$B$7*$B$8*$B$9*$B$10*(1-Parametros!$B$10) -> 1.5119934 | C18: W
A19: Duración de la órbita | B19: =Parametros!$B$7/60 -> 1.5941647 | C19: h
A20: Energía generada por órbita | B20: =B18*B19 -> 2.4103665 | C20: Wh
A21: Capacidad de batería | B21: =$B$12*$B$13*$B$14 -> 24.12 | C21: Wh
A23: Subsistema | B23: P nominal (W) | C23: P máxima (W) | D23: Ciclo órbita nominal | E23: Ciclo órbita peor caso | F23: Energía nominal (Wh) | G23: Energía peor caso (Wh) | H23: Fuente
A24: OBC (MCU + memorias) | B24: 0.35 | C24: 0.9 | D24: 1 | E24: 1 | F24: =B24*D24*$B$19 -> 0.55795763 | G24: =B24*E24*$B$19 -> 0.55795763 | H24: Tabla 8-4 [soaav]
A25: EPS (supervisión) | B25: 0.1 | C25: 0.15 | D25: 1 | E25: 1 | F25: =B25*D25*$B$19 -> 0.15941647 | G25: =B25*E25*$B$19 -> 0.15941647 | H25: Tablas 3-1, 3-4 [soapwr]
A26: ADCS sensores | B26: 0.12 | C26: 0.15 | D26: 1 | E26: 1 | F26: =B26*D26*$B$19 -> 0.19129976 | G26: =B26*E26*$B$19 -> 0.19129976 | H26: Tablas 5-6, 5-7 [soagnc]
A27: ADCS magnetorquers | B27: 0.15 | C27: 1.47 | D27: 0.25 | E27: 0.25 | F27: =B27*D27*$B$19 -> 0.059781175 | G27: =B27*E27*$B$19 -> 0.059781175 | H27: Tabla 5-4 [soagnc]
A28: ADCS ruedas (3) | B28: 0.45 | C28: 1.13 | D28: 0 | E28: 0.25 | F28: =B28*D28*$B$19 -> 0 | G28: =B28*E28*$B$19 -> 0.17934353 | H28: Tabla 5-3 [soagnc]
A29: UHF RX | B29: 0.24 | C29: 0.24 | D29: 1 | E29: 1 | F29: =B29*D29*$B$19 -> 0.38259952 | G29: =B29*E29*$B$19 -> 0.38259952 | H29: Pulsar-UTRX <240 mW [pulsarutrx]
A30: UHF TX (1 W RF) | B30: 5.5 | C30: 5.5 | D30: 0.02 | E30: 0.07 | F30: =B30*D30*$B$19 -> 0.17535811 | G30: =B30*E30*$B$19 -> 0.6137534 | H30: Pulsar-VUTRX 3-5,5 W [pulsarvutrx]
A31: Banda S TX (1 W RF) | B31: 5 | C31: 5 | D31: 0 | E31: 0.1 | F31: =B31*D31*$B$19 -> 0 | G31: =B31*E31*$B$19 -> 0.79708234 | H31: Pulsar-STXC <5 W [pulsarstx]
A32: Cámara | B32: 0.6 | C32: 0.8 | D32: 0 | E32: 0.03 | F32: =B32*D32*$B$19 -> 0 | G32: =B32*E32*$B$19 -> 0.028694964 | H32: Sensor 0,38 W [mt9p031] + reguladores
A33: Calentador de batería | B33: 0.4 | C33: 0.5 | D33: 0.15 | E33: 0.15 | F33: =B33*D33*$B$19 -> 0.09564988 | G33: =B33*E33*$B$19 -> 0.09564988 | H33: ET-27
A34: Total | F34: =SUM(F24:F33) -> 1.6220626 | G34: =SUM(G24:G33) -> 3.0655787
A35: Total con margen | F35: =F34*(1+$B$15) -> 1.9464751 | G35: =G34*(1+$B$15) -> 3.6786944
A37: Balance órbita nominal (Wh) | B37: =B20-F35 -> 0.46389142
A38: Balance órbita peor caso (Wh) | B38: =B20-G35 -> -1.2683279
A39: Balance diario con órbitas de peor caso (Wh) | B39: =Parametros!$B$12*B20-((Parametros!$B$12-$B$16)*F35+$B$16*G35) -> 1.7871839
A40: Energía de eclipse, peor caso (Wh) | B40: =G35*Parametros!$B$10 -> 1.3696177
A41: Profundidad de descarga peor órbita | B41: =(G35-B20+B40)/B21 -> 0.10936756
A42: Ciclos en 6 meses | B42: =Parametros!$B$12*182.5 -> 2747.5204
...

Sheet Masa_Volumen
A1: Elemento | B1: Masa (g) | C1: Fuente masa | D1: Altura en Z (mm) | E1: Observación
A2: EPS + batería 2S (P1) | B2: 180 | C2: Tabla 3-4 [soapwr] (2 celdas ≈ 100 g) | D2: 22 | E2: Celda de 18,5 mm + PCB + separación
A3: OBC-ADCS (P2) | B3: 50 | C3: Tabla 8-4 [soaav] | D3: 12 | E3: Componentes bajos
A4: Ruedas (3) con soporte | B4: 140 | C4: Tabla 5-3 [soagnc] | E4: En la bahía de carga útil
A5: COM (P3) con blindaje | B5: 195 | C5: TRXVU 75 g [trxvu] + TXS 120 g [txs] | D5: 13
A6: Cámara: lente, filtro, P4 | B6: 120 | C6: Estimación (S-08) | D6: 40 | E6: Bahía de carga útil (incluye ruedas)
A7: Antenas UHF y S | B7: 110 | C7: Tabla 9-2 [soacom] | D7: 5 | E7: Tapa +Z
A8: Estructura, paneles, magnetorquers, arnés | B8: 280 | C8: Estructura 115 g [spacemanic] + resto estimado
A9: Total | B9: =SUM(B2:B8) -> 1075 | D9: =SUM(D2:D8) -> 92
A10: Masa con margen 20 % | B10: =B9*1.2 -> 1290
A11: Límites (CDS / S-10) | B11: 2000 | D11: 95 | E11: Masa 1U ≤ 2,00 kg [cds]; altura útil 95 mm (S-10)
A12: Margen | B12: =B11-B10 -> 710 | D12: =D11-D9 -> 3

Sheet Datos
A1: Fuente | B1: Datos por adquisición (MB) | C1: Adquisiciones por día (promedio) | D1: Volumen por día (MB) | E1: Almacenamiento 7 días pico (MB) | F1: Tasa / canal
A2: Imagen 4 bandas (comprimida) | B2: =Parametros!$B$28 -> 49.128768 | C2: =Parametros!$B$47/7 -> 0.57142857 | D2: =B2*C2 -> 28.073582 | E2: =B2*7 -> 343.90138 | F2: Banda S 1 Mbps
A3: Miniaturas (20 kB × tomas) | B3: =0.02*Parametros!$B$26 -> 0.52 | C3: =C2 -> 0.57142857 | D3: =B3*C3 -> 0.29714286 | E3: =B3*7 -> 3.64 | F3: UHF o S
A4: Registro ADCS en captura (100 B a 10 Hz, 120 s) | B4: =100*10*120/10^6 -> 0.12 | C4: =C2 -> 0.57142857 | D4: =B4*C4 -> 0.068571429 | E4: =B4*7 -> 0.84 | F4: S
A5: Telemetría (200 B cada 60 s) | B5: =200/10^6 -> 0.0002 | C5: 1440 | D5: =B5*C5 -> 0.288 | E5: =D5*7 -> 2.016 | F5: UHF 9,6 kbps
A6: Total | D6: =SUM(D2:D5) -> 28.727296 | E6: =SUM(E2:E5) -> 350.39738
A8: Capacidad útil de banda S (MB/día) | B8: =Parametros!$B$45 -> 49.0875
A9: Uso de la capacidad S (promedio) | B9: =(D2+D3+D4)/B8 -> 0.57935923
A10: Días para descargar una sesión | B10: =B2/B8 -> 1.0008407
A11: Almacenamiento útil especificado (MB) | B11: 1000
A12: Cumple RNF-04 (7 días) | B12: =IF(E6<=B11,"Sí","No") -> Sí
A13: Cumple RNF-05 (≤ 2 días por sesión) | B13: =IF(B10<=2,"Sí","No") -> Sí

Sheet Enlace
A1: Parámetro | B1: UHF bajada | C1: S bajada | D1: Unidad / fuente
A2: Elevación mínima | B2: 10 | C2: 10 | D2: ° (S-03)
A3: Distancia máxima | B3: =SQRT((Parametros!$B$6)^2-(Parametros!$B$3*COS(RADIANS(B2)))^2)-Parametros!$B$3*SIN(RADIANS(B2)) -> 1815.6522 | C3: =SQRT((Parametros!$B$6)^2-(Parametros!$B$3*COS(RADIANS(C2)))^2)-Parametros!$B$3*SIN(RADIANS(C2)) -> 1815.6522 | D3: km
A4: Frecuencia | B4: 437 | C4: 2245 | D4: MHz
A5: Potencia TX | B5: 0 | C5: 0 | D5: dBW (30 dBm)
A6: Pérdida de línea TX | B6: 1 | C6: 1 | D6: dB
A7: Ganancia TX | B7: 0 | C7: 6 | D7: dBi (dipolo / parche, Tabla 9-2)
A8: Atmósfera + polarización | B8: 2 | C8: 2 | D8: dB
A9: Apuntamiento | B9: 3 | C9: 3 | D9: dB
A10: G/T del receptor | B10: =16.3-10*LOG10(290+290*(10^(2/10)-1)) -> -10.32398 | C10: 4.9 | D10: dB/K (Yagi 16,3 dBi, NF 2 dB / parábola 2 m) [isisgs, ntnugs]
A11: Tasa de datos | B11: 9600 | C11: 1000000 | D11: bit/s
A12: Eb/N0 requerido (S-13) | B12: 9.6 | C12: 4.1 | D12: dB [murota, ccsds130]
A13: PIRE | B13: =B5-B6+B7 -> -1 | C13: =C5-C6+C7 -> 5 | D13: dBW
A14: Pérdida de espacio libre | B14: =20*LOG10(4*PI()*B3*1000/(300000000/(B4*1000000))) -> 150.43205 | C14: =20*LOG10(4*PI()*C3*1000/(300000000/(C4*1000000))) -> 164.64675 | D14: dB
A15: C/N0 | B15: =B13-B14-B8-B9+B10+228.6 -> 61.843966 | C15: =C13-C14-C8-C9+C10+228.6 -> 68.853248 | D15: dBHz
A16: Eb/N0 obtenido | B16: =B15-10*LOG10(B11) -> 22.021254 | C16: =C15-10*LOG10(C11) -> 8.8532478 | D16: dB
A17: Margen | B17: =B16-B12 -> 12.421254 | C17: =C16-C12 -> 4.7532478 | D17: dB
A18: Cumple RNF-06 (≥ 3 dB) | B18: =IF(B17>=3,"Sí","No") -> Sí | C18: =IF(C17>=3,"Sí","No") -> Sí
A19: Margen con 1 dB de pérdida de implementación | B19: =B17-1 -> 11.421254 | C19: =C17-1 -> 3.7532478
A20: S bajada con parábola de 1,2 m (R-05) | C20: =C17-20*LOG10(2/1.2) -> 0.31627286
A22: Subida UHF (por sensibilidad) | B22: Valor | D22: Unidad / fuente
A23: Potencia TX estación | B23: 120 | D23: W [ntnugs]
A24: Pérdida de línea TX | B24: 2 | D24: dB
A25: Ganancia Yagi | B25: 16.3 | D25: dBi [ntnugs]
A26: Atmósfera + polarización | B26: 2 | D26: dB
A27: Apuntamiento | B27: 3 | D27: dB
A28: Ganancia antena satélite | B28: 0 | D28: dBi
A29: Pérdida de línea RX | B29: 1 | D29: dB
A30: Sensibilidad RX (BER 1E-5, FSK 9,6 kbps) | B30: -104 | D30: dBm [trxvu]
A31: Potencia recibida | B31: =10*LOG10(B23)+30-B24+B25-B14-B26-B27+B28-B29 -> -91.340242 | D31: dBm
A32: Margen | B32: =B31-B30 -> 12.659758 | D32: dB

Sheet Interfaces
A1: ID | B1: Origen | C1: Destino | D1: Función | E1: Señal / protocolo | F1: Características eléctricas prelim. | G1: Tasa / volumen | H1: Observaciones
A2: IF01* | B2: Paneles | C2: P1 | D2: Potencia solar | E2: 4 pares independientes | F2: 2 celdas en serie: V_mp≈4,8 V, I_mp≈0,5 A | G2: DC | H2: Diodo de bloqueo por cara; NTC por panel
A3: IF02 | B3: Batería | C3: P1 | D3: Almacenamiento | E3: Terminales + NTC | F3: 6,0--8,4 V, ≤3 A | G3: DC | H3: Fusible térmico/PTC en la celda
A4: IF03* | B4: P1 | C4: P2, P3, P4, ruedas | D4: Distribución | E4: Conector de apilado | F4: VBAT, 5V_SW (4 salidas), 3V3_SW (4 salidas), GND; ≤2 A por pin | G4: DC | H4: Retornos por pines dedicados; tierra en estrella en P1 [ecss20]
A5: IF04* | B5: P2 | C5: P1 | D5: Telemetría y comandos EPS | E5: I2C-1 + latido + reset (discretas) | F5: 3,3 V, pull-up en P2, 100 kHz | G5: ≈200 B/s | H5: Bus exclusivo EPS; P1 aislado si P2 apagado
A6: IF05* | B6: P2 | C6: P3 (UHF) | D6: TT&C | E6: UART + enable + reset | F6: 3,3 V, 115,2 kbaud | G6: 9,6 kbps | H6: Inhibidor FET en VBAT de radio
A7: IF06* | B7: P2 | C7: P3 (S) | D7: Datos de imagen | E7: SPI + enable + estado | F7: 3,3 V, ≥8 MHz | G7: 1 Mbps | H7: FIFO en transmisor
A8: IF07* | B8: P4 | C8: P2 | D8: Píxeles y configuración | E8: Paralelo 12 b + PIXCLK, HSYNC, VSYNC, XCLK, I2C-2, RESET | F8: Niveles 1,8--3,3 V con traductor de nivel en P4; cable FFC ≤80 mm | G8: 96 MB/s ráfagas | H8: Tierras intercaladas en FFC; igualar longitudes
A9: IF08* | B9: P2 | C9: Bobinas MTQ | D9: Actuación magnética | E9: PWM a puente H | F9: 5 V, ≤120 mA por eje | G9: 10 Hz | H9: Medición de corriente por eje
A10: IF09* | B10: P2, P1 | C10: Ruedas | D10: Actuación fina | E10: UART + 5V_SW | F10: 3,3 V lógica; pico 1,5 W total | G10: 10 Hz | H10: Controlador de velocidad en la rueda
A11: IF10* | B11: Paneles | C11: P2 | D11: Sensores solares, temperatura | E11: Analógico (fotodiodos) | F11: 0--3,3 V, filtrado RC | G11: 10 Hz | H11: Pares trenzados con retorno propio
A12: IF11 | B12: P3 | C12: Antenas | D12: RF | E12: Coaxial 50 Ω | F12: UHF 30 dBm; S 30 dBm | G12: -- | H12: Pérdida ≤1 dB
... A15: IF14* | B15: Umbilical | C15: P1, P2 | D15: Carga, depuración | E15: SWD + UART + carga externa | F15: 3,3 V; carga ≤8,4 V | G15: -- | H15: Por puerto de acceso (RNF-15)

Sheet Riesgos
A1: ID | B1: Riesgo | C1: Consecuencia | D1: Mitigación / acción pendiente
A2: R-01 | B2: Altura de apilado insuficiente (margen 3 mm). | C2: No cabe el sistema. | D2: Exigir ≥95 mm útiles al seleccionar la estructura (S-10); plan B: integrar COM en P2 (D2-B), que libera 13 mm.
A3: R-02 | B3: Baja oferta de sensores con salida paralela. | C3: Cambio de la interfaz de cámara. | D3: Si el sensor elegido solo ofrece MIPI, añadir un puente MIPI--paralelo en P4; IF07 no cambia hacia P2.
A4: R-03 | B4: Filtro de franjas a medida (costo y plazo). | C4: Retraso de la carga útil. | D4: Cotizar temprano; alternativa: cuatro filtros comerciales cortados y pegados con máscara.
A5: R-04 | B5: Nubosidad sobre la zona cafetera. | C5: Imágenes inútiles, datos desperdiciados. | D5: Miniaturas por UHF para elegir qué descargar; capturas en la mañana (S-01).
A6: R-05 | B6: La estación de Medellín solo dispone de parábola de 1,2 m. | C6: Margen S de 0,3 dB (<3 dB). | D6: Reducir a 512 kbps (margen 3,2 dB) y descargar en dos pases.
A7: R-06 | B7: SEL/SEU en componentes COTS. | C7: Pérdida de funciones o reinicios. | D7: LCL con reconexión, watchdog externo, ECC y doble arranque [soaav].
A8: R-07 | B8: SNR insuficiente en NIR (baja eficiencia cuántica del silicio). | C8: Índices ruidosos. | D8: Banda NIR ancha (ET-01), exposición y ganancia ajustables, y agrupación de píxeles 2×2 (GSD 97 m) si la señal es baja.
A9: R-08 | B9: OBC como punto único de falla. | C9: Pérdida de la misión. | D9: EPS autónoma y supervisora; modo seguro; actualización de software en órbita.
A10: R-09 | B10: Licencias: la banda de aficionados prohíbe cifrado y uso con fines de lucro. | C10: Restricción de operación. | D10: Datos abiertos; trámite ante la ANE y coordinación IARU iniciados al congelar frecuencias [soacom].
